Workbook

Sheet Cockpit
B1: Cockpit – Lagerlift-Belegung & MAX-Bestand nach Lagerumschlag
B2: ="Verbrauchsbasis: "&TEXT(MONTH(Parameter!B15),"00")&"."&YEAR(Parameter!B15)&" – "&TEXT(MONTH(Parameter!B16),"00")&"."&YEAR(Parameter!B16)&" · Ist-Bestand: "&Parameter!B20&" · Kapazität "&Parameter!E8&" Tablare (Füllgrad über Gebinde je Tablar)" -> Verbrauchsbasis: 01.2025 – 12.2025 · Ist-Bestand: Jahresanfang 2025 + Export · Kapazität 150 Tablare (Füllgrad über Gebinde je Tablar)
B3: Gelbe Felder = Regler. Auslastung: grün < 85 %, orange 85–100 %, rot > 100 %.
B4: Ansicht 1 | H4: Ansicht 2 | N4: Ansicht 3
B5: Variante | C5: A – Ist-Bestand | H5: Variante | I5: C – Ziel-LU oder Ist | N5: Variante | O5: C – Ziel-LU oder Ist
B6: Ziel-LU | C6: 2 | D6: (bei A ohne Wirkung) | H6: Ziel-LU | I6: 2 | J6: (bei A ohne Wirkung) | N6: Ziel-LU | O6: 3 | P6: (bei A ohne Wirkung)
B8: Bereich | C8: Tablare Bedarf | D8: Tablare vorhanden | E8: Tablare frei | F8: Füllgrad | H8: Bereich | I8: Tablare Bedarf | J8: Tablare vorhanden | K8: Tablare frei | L8: Füllgrad | N8: Bereich | O8: Tablare Bedarf | P8: Tablare vorhanden | Q8: Tablare frei | R8: Füllgrad
B9: Lift 1 – Schwer | C9: =SUMIFS(Artikel!$AH$7:$AH$1843,Artikel!$BX$7:$BX$1843,1) -> 54.032887 | D9: =Parameter!$E$5 -> 50 | E9: =D9-C9 -> -4.0328874 | F9: =IF(D9>0,C9/D9,0) -> 1.0806577 | H9: Lift 1 – Schwer | I9: =SUMIFS(Artikel!$AP$7:$AP$1843,Artikel!$BX$7:$BX$1843,1) -> 70.99305 | J9: =Parameter!$E$5 -> 50 | K9: =J9-I9 -> -20.99305 | L9: =IF(J9>0,I9/J9,0) -> 1.419861 | N9: Lift 1 – Schwer | O9: =SUMIFS(Artikel!$AX$7:$AX$1843,Artikel!$BX$7:$BX$1843,1) -> 64.659861 | P9: =Parameter!$E$5 -> 50 | Q9: =P9-O9 -> -14.659861 | R9: =IF(P9>0,O9/P9,0) -> 1.2931972
B10: Lift 2 – Mittel | C10: =SUMIFS(Artikel!$AH$7:$AH$1843,Artikel!$BX$7:$BX$1843,2) -> 66.674242 | D10: =Parameter!$E$6 -> 50 | E10: =D10-C10 -> -16.674242 | F10: =IF(D10>0,C10/D10,0) -> 1.3334848 | H10: Lift 2 – Mittel | I10: =SUMIFS(Artikel!$AP$7:$AP$1843,Artikel!$BX$7:$BX$1843,2) -> 103.17424 | J10: =Parameter!$E$6 -> 50 | K10: =J10-I10 -> -53.174242 | L10: =IF(J10>0,I10/J10,0) -> 2.0634848 | N10: Lift 2 – Mittel | O10: =SUMIFS(Artikel!$AX$7:$AX$1843,Artikel!$BX$7:$BX$1843,2) -> 95.007576 | P10: =Parameter!$E$6 -> 50 | Q10: =P10-O10 -> -45.007576 | R10: =IF(P10>0,O10/P10,0) -> 1.9001515
B11: Lift 3 – Klein | C11: =SUMIFS(Artikel!$AH$7:$AH$1843,Artikel!$BX$7:$BX$1843,3) -> 30.207459 | D11: =Parameter!$E$7 -> 50 | E11: =D11-C11 -> 19.792541 | F11: =IF(D11>0,C11/D11,0) -> 0.60414918 | H11: Lift 3 – Klein | I11: =SUMIFS(Artikel!$AP$7:$AP$1843,Artikel!$BX$7:$BX$1843,3) -> 39.072903 | J11: =Parameter!$E$7 -> 50 | K11: =J11-I11 -> 10.927097 | L11: =IF(J11>0,I11/J11,0) -> 0.78145806 | N11: Lift 3 – Klein | O11: =SUMIFS(Artikel!$AX$7:$AX$1843,Artikel!$BX$7:$BX$1843,3) -> 38.069406 | P11: =Parameter!$E$7 -> 50 | Q11: =P11-O11 -> 11.930594 | R11: =IF(P11>0,O11/P11,0) -> 0.76138813
B12: Lift 2 + 3 gemeinsam (KTL/PAL) | C12: =C10+C11 -> 96.881702 | D12: =D10+D11 -> 100 | E12: =D12-C12 -> 3.1182984 | F12: =IF(D12>0,C12/D12,0) -> 0.96881702 | H12: Lift 2 + 3 gemeinsam (KTL/PAL) | I12: =I10+I11 -> 142.24715 | J12: =J10+J11 -> 100 | K12: =J12-I12 -> -42.247145 | L12: =IF(J12>0,I12/J12,0) -> 1.4224715 | N12: Lift 2 + 3 gemeinsam (KTL/PAL) | O12: =O10+O11 -> 133.07698 | P12: =P10+P11 -> 100 | Q12: =P12-O12 -> -33.076982 | R12: =IF(P12>0,O12/P12,0) -> 1.3307698
B13: Total 3 Lifte | C13: =C9+C12 -> 150.91459 | D13: =D9+D12 -> 150 | E13: =D13-C13 -> -0.91458903 | F13: =IF(D13>0,C13/D13,0) -> 1.0060973 | H13: Total 3 Lifte | I13: =I9+I12 -> 213.2402 | J13: =J9+J12 -> 150 | K13: =J13-I13 -> -63.240195 | L13: =IF(J13>0,I13/J13,0) -> 1.4216013 | N13: Total 3 Lifte | O13: =O9+O12 -> 197.73684 | P13: =P9+P12 -> 150 | Q13: =P13-O13 -> -47.736843 | R13: =IF(P13>0,O13/P13,0) -> 1.3182456
B14: Nicht im Lift (andere Hauptlager) | C14: =SUMIFS(Artikel!$AH$7:$AH$1843,Artikel!$BY$7:$BY$1843,"-") -> 15.348485 | H14: Nicht im Lift (andere Hauptlager) | I14: =SUMIFS(Artikel!$AP$7:$AP$1843,Artikel!$BY$7:$BY$1843,"-") -> 77.309274 | N14: Nicht im Lift (andere Hauptlager) | O14: =SUMIFS(Artikel!$AX$7:$AX$1843,Artikel!$BY$7:$BY$1843,"-") -> 72.850419
B15: Manuell «Aussen» zugeteilt | C15: =SUMIFS(Artikel!$AH$7:$AH$1843,Artikel!$BY$7:$BY$1843,"Aussen") -> 0 | H15: Manuell «Aussen» zugeteilt | I15: =SUMIFS(Artikel!$AP$7:$AP$1843,Artikel!$BY$7:$BY$1843,"Aussen") -> 0 | N15: Manuell «Aussen» zugeteilt | O15: =SUMIFS(Artikel!$AX$7:$AX$1843,Artikel!$BY$7:$BY$1843,"Aussen") -> 0
B17: Passt alles in die 3 Lifte? | E17: =IF(AND(C9<=D9,C12<=D12),"JA","NEIN") -> NEIN | H17: Passt alles in die 3 Lifte? | K17: =IF(AND(I9<=J9,I12<=J12),"JA","NEIN") -> NEIN | N17: Passt alles in die 3 Lifte? | Q17: =IF(AND(O9<=P9,O12<=P12),"JA","NEIN") -> NEIN
B18: Lift 1 (schwer, separat) | D18: =IF(C9<=D9,"JA","NEIN") -> NEIN | H18: Lift 1 (schwer, separat) | J18: =IF(I9<=J9,"JA","NEIN") -> NEIN | N18: Lift 1 (schwer, separat) | P18: =IF(O9<=P9,"JA","NEIN") -> NEIN
B19: Lift 2 + 3 gemeinsam | D19: =IF(C12<=D12,"JA","NEIN") -> JA | H19: Lift 2 + 3 gemeinsam | J19: =IF(I12<=J12,"JA","NEIN") -> NEIN | N19: Lift 2 + 3 gemeinsam | P19: =IF(O12<=P12,"JA","NEIN") -> NEIN
B20: =IF(OR(AND(C10>D10,C11<D11),AND(C11>D11,C10<D10)),"Ausgleich Lift 2 ↔ 3 möglich: "&ROUNDUP(MIN(MAX(C10-D10,C11-D11),MAX(D10-C10,D11-C11)),0)&" Tablare","") -> Ausgleich Lift 2 ↔ 3 möglich: 17 Tablare | H20: =IF(OR(AND(I10>J10,I11<J11),AND(I11>J11,I10<J10)),"Ausgleich Lift 2 ↔ 3 möglich: "&ROUNDUP(MIN(MAX(I10-J10,I11-J11),MAX(J10-I10,J11-I11)),0)&" Tablare","") -> Ausgleich Lift 2 ↔ 3 möglich: 11 Tablare | N20: =IF(OR(AND(O10>P10,O11<P11),AND(O11>P11,O10<P10)),"Ausgleich Lift 2 ↔ 3 möglich: "&ROUNDUP(MIN(MAX(O10-P10,O11-P11),MAX(P10-O10,P11-O11)),0)&" Tablare","") -> Ausgleich Lift 2 ↔ 3 möglich: 12 Tablare
B22: Aussenlager nötig (Tablare) | D22: =MAX(0,C9-D9)+MAX(0,C12-D12)+C15 -> 4.0328874 | H22: Aussenlager nötig (Tablare) | J22: =MAX(0,I9-J9)+MAX(0,I12-J12)+I15 -> 63.240195 | N22: Aussenlager nötig (Tablare) | P22: =MAX(0,O9-P9)+MAX(0,O12-P12)+O15 -> 47.736843
B23: Artikel im Aussenlager (ganz/teilweise) | D23: =COUNTIF(Artikel!$BD$7:$BD$1843,"Aussenlager")+COUNTIF(Artikel!$BD$7:$BD$1843,"teilweise") -> 21 | H23: Artikel im Aussenlager (ganz/teilweise) | J23: =COUNTIF(Artikel!$BE$7:$BE$1843,"Aussenlager")+COUNTIF(Artikel!$BE$7:$BE$1843,"teilweise") -> 602 | N23: Artikel im Aussenlager (ganz/teilweise) | P23: =COUNTIF(Artikel!$BF$7:$BF$1843,"Aussenlager")+COUNTIF(Artikel!$BF$7:$BF$1843,"teilweise") -> 563
B25: Lagerwert CHF gesamt | D25: =SUM(Artikel!$AI$7:$AI$1843) -> 3451046.2 | H25: Lagerwert CHF gesamt | J25: =SUM(Artikel!$AQ$7:$AQ$1843) -> 7904043 | N25: Lagerwert CHF gesamt | P25: =SUM(Artikel!$AY$7:$AY$1843) -> 6965579.7
B26: davon in den Liften | D26: =SUMPRODUCT(Artikel!$AI$7:$AI$1843,Artikel!$AM$7:$AM$1843) -> 3063330.6 | H26: davon in den Liften | J26: =SUMPRODUCT(Artikel!$AQ$7:$AQ$1843,Artikel!$AU$7:$AU$1843) -> 5451203.8 | N26: davon in den Liften | P26: =SUMPRODUCT(Artikel!$AY$7:$AY$1843,Artikel!$BC$7:$BC$1843) -> 5161476.9
B27: davon im Aussenlager | D27: =SUMIFS(Artikel!$AI$7:$AI$1843,Artikel!$BY$7:$BY$1843,"L1")+SUMIFS(Artikel!$AI$7:$AI$1843,Artikel!$BY$7:$BY$1843,"L23")-D26+SUMIFS(Artikel!$AI$7:$AI$1843,Artikel!$BY$7:$BY$1843,"Aussen") -> 105254.54 | H27: davon im Aussenlager | J27: =SUMIFS(Artikel!$AQ$7:$AQ$1843,Artikel!$BY$7:$BY$1843,"L1")+SUMIFS(Artikel!$AQ$7:$AQ$1843,Artikel!$BY$7:$BY$1843,"L23")-J26+SUMIFS(Artikel!$AQ$7:$AQ$1843,Artikel!$BY$7:$BY$1843,"Aussen") -> 1447481.3 | N27: davon im Aussenlager | P27: =SUMIFS(Artikel!$AY$7:$AY$1843,Artikel!$BY$7:$BY$1843,"L1")+SUMIFS(Artikel!$AY$7:$AY$1843,Artikel!$BY$7:$BY$1843,"L23")-P26+SUMIFS(Artikel!$AY$7:$AY$1843,Artikel!$BY$7:$BY$1843,"Aussen") -> 1022449.3
B28: davon nicht im Lift (andere Lager) | D28: =SUMIFS(Artikel!$AI$7:$AI$1843,Artikel!$BY$7:$BY$1843,"-") -> 282461.1 | H28: davon nicht im Lift (andere Lager) | J28: =SUMIFS(Artikel!$AQ$7:$AQ$1843,Artikel!$BY$7:$BY$1843,"-") -> 1005358 | N28: davon nicht im Lift (andere Lager) | P28: =SUMIFS(Artikel!$AY$7:$AY$1843,Artikel!$BY$7:$BY$1843,"-") -> 781653.55
B30: Artikel mit Überbestand (Ist > MAX B) | D30: =SUMPRODUCT((Artikel!$H$7:$H$1843>Artikel!$AJ$7:$AJ$1843)*1) -> 174 | E30: (LU dieser Ansicht) | H30: Artikel mit Überbestand (Ist > MAX B) | J30: =SUMPRODUCT((Artikel!$H$7:$H$1843>Artikel!$AR$7:$AR$1843)*1) -> 174 | K30: (LU dieser Ansicht) | N30: Artikel mit Überbestand (Ist > MAX B) | P30: =SUMPRODUCT((Artikel!$H$7:$H$1843>Artikel!$AZ$7:$AZ$1843)*1) -> 178 | Q30: (LU dieser Ansicht)
B31: Überbestandswert CHF | D31: =SUMPRODUCT((Artikel!$H$7:$H$1843>Artikel!$AJ$7:$AJ$1843)*(Artikel!$H$7:$H$1843-Artikel!$AJ$7:$AJ$1843)*Artikel!$G$7:$G$1843) -> 355656.61 | H31: Überbestandswert CHF | J31: =SUMPRODUCT((Artikel!$H$7:$H$1843>Artikel!$AR$7:$AR$1843)*(Artikel!$H$7:$H$1843-Artikel!$AR$7:$AR$1843)*Artikel!$G$7:$G$1843) -> 355656.61 | N31: Überbestandswert CHF | P31: =SUMPRODUCT((Artikel!$H$7:$H$1843>Artikel!$AZ$7:$AZ$1843)*(Artikel!$H$7:$H$1843-Artikel!$AZ$7:$AZ$1843)*Artikel!$G$7:$G$1843) -> 368368.42
B33: Tablare je Lift | C33: aus Gebinden (Stammdaten) | D33: Fächer lt. Liftbericht | E33: lose (grob geschätzt) | F33: Anteil geschätzt | H33: Tablare je Lift | I33: aus Gebinden (Stammdaten) | J33: Fächer lt. Liftbericht | K33: lose (grob geschätzt) | L33: Anteil geschätzt | N33: Tablare je Lift | O33: aus Gebinden (Stammdaten) | P33: Fächer lt. Liftbericht | Q33: lose (grob geschätzt) | R33: Anteil geschätzt
B34: Lift 1 – Schwer | C34: =SUMIFS(Artikel!$AH$7:$AH$1843,Artikel!$BX$7:$BX$1843,1,Artikel!$BT$7:$BT$1843,0,Artikel!$CH$7:$CH$1843,0,Artikel!$BU$7:$BU$1843,0) -> 11.032887 | D34: =SUMIFS(Artikel!$AH$7:$AH$1843,Artikel!$BX$7:$BX$1843,1,Artikel!$CH$7:$CH$1843,">0") -> 42.5 | E34: =SUMIFS(Artikel!$AH$7:$AH$1843,Artikel!$BX$7:$BX$1843,1,Artikel!$BT$7:$BT$1843,1,Artikel!$CH$7:$CH$1843,0)+SUMIFS(Artikel!$AH$7:$AH$1843,Artikel!$BX$7:$BX$1843,1,Artikel!$BU$7:$BU$1843,1,Artikel!$CH$7:$CH$1843,0) -> 0.5 | F34: =IF(SUM(C34:E34)>0,E34/SUM(C34:E34),0) -> 0.0092536236 | H34: Lift 1 – Schwer | I34: =SUMIFS(Artikel!$AP$7:$AP$1843,Artikel!$BX$7:$BX$1843,1,Artikel!$BT$7:$BT$1843,0,Artikel!$CH$7:$CH$1843,0,Artikel!$BU$7:$BU$1843,0) -> 19.321349 | J34: =SUMIFS(Artikel!$AP$7:$AP$1843,Artikel!$BX$7:$BX$1843,1,Artikel!$CH$7:$CH$1843,">0") -> 49.383239 | K34: =SUMIFS(Artikel!$AP$7:$AP$1843,Artikel!$BX$7:$BX$1843,1,Artikel!$BT$7:$BT$1843,1,Artikel!$CH$7:$CH$1843,0)+SUMIFS(Artikel!$AP$7:$AP$1843,Artikel!$BX$7:$BX$1843,1,Artikel!$BU$7:$BU$1843,1,Artikel!$CH$7:$CH$1843,0) -> 2.2884615 | L34: =IF(SUM(I34:K34)>0,K34/SUM(I34:K34),0) -> 0.032235008 | N34: Lift 1 – Schwer | O34: =SUMIFS(Artikel!$AX$7:$AX$1843,Artikel!$BX$7:$BX$1843,1,Artikel!$BT$7:$BT$1843,0,Artikel!$CH$7:$CH$1843,0,Artikel!$BU$7:$BU$1843,0) -> 16.282887 | P34: =SUMIFS(Artikel!$AX$7:$AX$1843,Artikel!$BX$7:$BX$1843,1,Artikel!$CH$7:$CH$1843,">0") -> 46.421846 | Q34: =SUMIFS(Artikel!$AX$7:$AX$1843,Artikel!$BX$7:$BX$1843,1,Artikel!$BT$7:$BT$1843,1,Artikel!$CH$7:$CH$1843,0)+SUMIFS(Artikel!$AX$7:$AX$1843,Artikel!$BX$7:$BX$1843,1,Artikel!$BU$7:$BU$1843,1,Artikel!$CH$7:$CH$1843,0) -> 1.9551282 | R34: =IF(SUM(O34:Q34)>0,Q34/SUM(O34:Q34),0) -> 0.030237123
B35: Lift 2 – Mittel | C35: =SUMIFS(Artikel!$AH$7:$AH$1843,Artikel!$BX$7:$BX$1843,2,Artikel!$BT$7:$BT$1843,0,Artikel!$CH$7:$CH$1843,0,Artikel!$BU$7:$BU$1843,0) -> 49.340909 | D35: =SUMIFS(Artikel!$AH$7:$AH$1843,Artikel!$BX$7:$BX$1843,2,Artikel!$CH$7:$CH$1843,">0") -> 0 | E35: =SUMIFS(Artikel!$AH$7:$AH$1843,Artikel!$BX$7:$BX$1843,2,Artikel!$BT$7:$BT$1843,1,Artikel!$CH$7:$CH$1843,0)+SUMIFS(Artikel!$AH$7:$AH$1843,Artikel!$BX$7:$BX$1843,2,Artikel!$BU$7:$BU$1843,1,Artikel!$CH$7:$CH$1843,0) -> 17.333333 | F35: =IF(SUM(C35:E35)>0,E35/SUM(C35:E35),0) -> 0.25997046 | H35: Lift 2 – Mittel | I35: =SUMIFS(Artikel!$AP$7:$AP$1843,Artikel!$BX$7:$BX$1843,2,Artikel!$BT$7:$BT$1843,0,Artikel!$CH$7:$CH$1843,0,Artikel!$BU$7:$BU$1843,0) -> 63.757576 | J35: =SUMIFS(Artikel!$AP$7:$AP$1843,Artikel!$BX$7:$BX$1843,2,Artikel!$CH$7:$CH$1843,">0") -> 0 | K35: =SUMIFS(Artikel!$AP$7:$AP$1843,Artikel!$BX$7:$BX$1843,2,Artikel!$BT$7:$BT$1843,1,Artikel!$CH$7:$CH$1843,0)+SUMIFS(Artikel!$AP$7:$AP$1843,Artikel!$BX$7:$BX$1843,2,Artikel!$BU$7:$BU$1843,1,Artikel!$CH$7:$CH$1843,0) -> 39.416667 | L35: =IF(SUM(I35:K35)>0,K35/SUM(I35:K35),0) -> 0.3820398 | N35: Lift 2 – Mittel | O35: =SUMIFS(Artikel!$AX$7:$AX$1843,Artikel!$BX$7:$BX$1843,2,Artikel!$BT$7:$BT$1843,0,Artikel!$CH$7:$CH$1843,0,Artikel!$BU$7:$BU$1843,0) -> 60.674242 | P35: =SUMIFS(Artikel!$AX$7:$AX$1843,Artikel!$BX$7:$BX$1843,2,Artikel!$CH$7:$CH$1843,">0") -> 0 | Q35: =SUMIFS(Artikel!$AX$7:$AX$1843,Artikel!$BX$7:$BX$1843,2,Artikel!$BT$7:$BT$1843,1,Artikel!$CH$7:$CH$1843,0)+SUMIFS(Artikel!$AX$7:$AX$1843,Artikel!$BX$7:$BX$1843,2,Artikel!$BU$7:$BU$1843,1,Artikel!$CH$7:$CH$1843,0) -> 34.333333 | R35: =IF(SUM(O35:Q35)>0,Q35/SUM(O35:Q35),0) -> 0.36137469
B36: Lift 3 – Klein | C36: =SUMIFS(Artikel!$AH$7:$AH$1843,Artikel!$BX$7:$BX$1843,3,Artikel!$BT$7:$BT$1843,0,Artikel!$CH$7:$CH$1843,0,Artikel!$BU$7:$BU$1843,0) -> 24.438228 | D36: =SUMIFS(Artikel!$AH$7:$AH$1843,Artikel!$BX$7:$BX$1843,3,Artikel!$CH$7:$CH$1843,">0") -> 0 | E36: =SUMIFS(Artikel!$AH$7:$AH$1843,Artikel!$BX$7:$BX$1843,3,Artikel!$BT$7:$BT$1843,1,Artikel!$CH$7:$CH$1843,0)+SUMIFS(Artikel!$AH$7:$AH$1843,Artikel!$BX$7:$BX$1843,3,Artikel!$BU$7:$BU$1843,1,Artikel!$CH$7:$CH$1843,0) -> 5.7692308 | F36: =IF(SUM(C36:E36)>0,E36/SUM(C36:E36),0) -> 0.19098696 | H36: Lift 3 – Klein | I36: =SUMIFS(Artikel!$AP$7:$AP$1843,Artikel!$BX$7:$BX$1843,3,Artikel!$BT$7:$BT$1843,0,Artikel!$CH$7:$CH$1843,0,Artikel!$BU$7:$BU$1843,0) -> 29.49598 | J36: =SUMIFS(Artikel!$AP$7:$AP$1843,Artikel!$BX$7:$BX$1843,3,Artikel!$CH$7:$CH$1843,">0") -> 0 | K36: =SUMIFS(Artikel!$AP$7:$AP$1843,Artikel!$BX$7:$BX$1843,3,Artikel!$BT$7:$BT$1843,1,Artikel!$CH$7:$CH$1843,0)+SUMIFS(Artikel!$AP$7:$AP$1843,Artikel!$BX$7:$BX$1843,3,Artikel!$BU$7:$BU$1843,1,Artikel!$CH$7:$CH$1843,0) -> 9.5769231 | L36: =IF(SUM(I36:K36)>0,K36/SUM(I36:K36),0) -> 0.24510396 | N36: Lift 3 – Klein | O36: =SUMIFS(Artikel!$AX$7:$AX$1843,Artikel!$BX$7:$BX$1843,3,Artikel!$BT$7:$BT$1843,0,Artikel!$CH$7:$CH$1843,0,Artikel!$BU$7:$BU$1843,0) -> 29.14633 | P36: =SUMIFS(Artikel!$AX$7:$AX$1843,Artikel!$BX$7:$BX$1843,3,Artikel!$CH$7:$CH$1843,">0") -> 0 | Q36: =SUMIFS(Artikel!$AX$7:$AX$1843,Artikel!$BX$7:$BX$1843,3,Artikel!$BT$7:$BT$1843,1,Artikel!$CH$7:$CH$1843,0)+SUMIFS(Artikel!$AX$7:$AX$1843,Artikel!$BX$7:$BX$1843,3,Artikel!$BU$7:$BU$1843,1,Artikel!$CH$7:$CH$1843,0) -> 8.9230769 | R36: =IF(SUM(O36:Q36)>0,Q36/SUM(O36:Q36),0) -> 0.2343897
B37: Total | C37: =SUM(C34:C36) -> 84.812025 | D37: =SUM(D34:D36) -> 42.5 | E37: =SUM(E34:E36) -> 23.602564 | F37: =IF(SUM(C37:E37)>0,E37/SUM(C37:E37),0) -> 0.15639684 | H37: Total | I37: =SUM(I34:I36) -> 112.5749 | J37: =SUM(J34:J36) -> 49.383239 | K37: =SUM(K34:K36) -> 51.282051 | L37: =IF(SUM(I37:K37)>0,K37/SUM(I37:K37),0) -> 0.24048961 | N37: Total | O37: =SUM(O34:O36) -> 106.10346 | P37: =SUM(P34:P36) -> 46.421846 | Q37: =SUM(Q34:Q36) -> 45.211538 | R37: =IF(SUM(O37:Q37)>0,Q37/SUM(O37:Q37),0) -> 0.22864499
B40: Diagrammdaten (Auslastung %) | C40: ="A1: "&LEFT(C5,1)&IF(LEFT(C5,1)="A",""," LU "&C6) -> A1: A | D40: ="A2: "&LEFT(I5,1)&IF(LEFT(I5,1)="A",""," LU "&I6) -> A2: C LU 2 | E40: ="A3: "&LEFT(O5,1)&IF(LEFT(O5,1)="A",""," LU "&O6) -> A3: C LU 3 | F40: 100 %
B41: Lift 1 | C41: =F9 -> 1.0806577 | D41: =L9 -> 1.419861 | E41: =R9 -> 1.2931972 | F41: 1
B42: Lift 2 | C42: =F10 -> 1.3334848 | D42: =L10 -> 2.0634848 | E42: =R10 -> 1.9001515 | F42: 1
B43: Lift 3 | C43: =F11 -> 0.60414918 | D43: =L11 -> 0.78145806 | E43: =R11 -> 0.76138813 | F43: 1
B44: Lift 2+3 | C44: =F12 -> 0.96881702 | D44: =L12 -> 1.4224715 | E44: =R12 -> 1.3307698 | F44: 1
B45: Total | C45: =F13 -> 1.0060973 | D45: =L13 -> 1.4216013 | E45: =R13 -> 1.3182456 | F45: 1

Sheet Szenarien
A1: Szenarien – alle LU-Werte auf einen Blick
A2: Berechnung direkt über das Blatt «Artikel» (SUMPRODUCT). Berücksichtigt Lift-Zuordnung, Gebinde-Anpassungen, Ziel-LU je Artikel und MAX final. LU-Werte aus Parameter A23:A30.
A4: Variante | B4: Ziel-LU | C4: Lift 1 % | D4: Lift 2 % | E4: Lift 3 % | F4: Lift 2+3 % | G4: Total % | H4: Passt alles? | I4: Aussenlager Tablare | J4: Lagerwert CHF | K4: Δ zum Ist CHF | L4: Δ zum Ist Tablare | M4: Lift 1 Tablare | N4: Lift 2 Tablare | O4: Lift 3 Tablare | P4: Aussen manuell Tablare
A5: Ist-Bestand | B5: – | C5: =M5/Parameter!$E$5 -> 1.0806577 | D5: =N5/Parameter!$E$6 -> 1.3334848 | E5: =O5/Parameter!$E$7 -> 0.60414918 | F5: =(N5+O5)/(Parameter!$E$6+Parameter!$E$7) -> 0.96881702 | G5: =(M5+N5+O5)/Parameter!$E$8 -> 1.0060973 | H5: =IF(AND(M5<=Parameter!$E$5,N5+O5<=Parameter!$E$6+Parameter!$E$7),"JA","NEIN") -> NEIN | I5: =MAX(0,M5-Parameter!$E$5)+MAX(0,N5+O5-Parameter!$E$6-Parameter!$E$7)+P5 -> 4.0328874 | J5: =SUMPRODUCT(A_IST*A_PREIS) -> 3451046.2 | K5: =J5-$J$5 -> 0 | L5: =(M5+N5+O5+P5)-($M$5+$N$5+$O$5+$P$5) -> 0 | M5: =SUMPRODUCT((A_LIFT=1)*((A_FACH>0)*A_FACH*(1+(A_KAPR>0)*(A_IST>A_KAPR)*(A_IST/(A_KAPR+(A_KAPR=0))-1))+(A_FACH=0)*((1-A_LOSE)*(A_GPT>0)*A_ISTN/(A_GPT+(A_GPT=0))+A_LOSE*(A_IST>0)*A_LA*(1+(A_IST>0)*(A_IST>A_IST)*(A_IST/(A_IST+(A_IST=0))-1)))/MAX(0.1,N(Parameter!$M$21)))) -> 54.032887 | N5: =SUMPRODUCT((A_LIFT=2)*((A_FACH>0)*A_FACH*(1+(A_KAPR>0)*(A_IST>A_KAPR)*(A_IST/(A_KAPR+(A_KAPR=0))-1))+(A_FACH=0)*((1-A_LOSE)*(A_GPT>0)*A_ISTN/(A_GPT+(A_GPT=0))+A_LOSE*(A_IST>0)*A_LA*(1+(A_IST>0)*(A_IST>A_IST)*(A_IST/(A_IST+(A_IST=0))-1)))/MAX(0.1,N(Parameter!$M$21)))) -> 66.674242 | O5: =SUMPRODUCT((A_LIFT=3)*((A_FACH>0)*A_FACH*(1+(A_KAPR>0)*(A_IST>A_KAPR)*(A_IST/(A_KAPR+(A_KAPR=0))-1))+(A_FACH=0)*((1-A_LOSE)*(A_GPT>0)*A_ISTN/(A_GPT+(A_GPT=0))+A_LOSE*(A_IST>0)*A_LA*(1+(A_IST>0)*(A_IST>A_IST)*(A_IST/(A_IST+(A_IST=0))-1)))/MAX(0.1,N(Parameter!$M$21)))) -> 30.207459 | P5: =SUMPRODUCT((A_LIFT="Aussen")*((A_FACH>0)*A_FACH*(1+(A_KAPR>0)*(A_IST>A_KAPR)*(A_IST/(A_KAPR+(A_KAPR=0))-1))+(A_FACH=0)*((1-A_LOSE)*(A_GPT>0)*A_ISTN/(A_GPT+(A_GPT=0))+A_LOSE*(A_IST>0)*A_LA*(1+(A_IST>0)*(A_IST>A_IST)*(A_IST/(A_IST+(A_IST=0))-1)))/MAX(0.1,N(Parameter!$M$21)))) -> 0
A6: B – Ziel-LU | B6: =Parameter!$A$23 -> 1 | C6: =M6/Parameter!$E$5 -> 2.0707121 | D6: =N6/Parameter!$E$6 -> 2.4568182 | E6: =O6/Parameter!$E$7 -> 0.81154691 | F6: =(N6+O6)/(Parameter!$E$6+Parameter!$E$7) -> 1.6341825 | G6: =(M6+N6+O6)/Parameter!$E$8 -> 1.7796924 | H6: =IF(AND(M6<=Parameter!$E$5,N6+O6<=Parameter!$E$6+Parameter!$E$7),"JA","NEIN") -> NEIN | I6: =MAX(0,M6-Parameter!$E$5)+MAX(0,N6+O6-Parameter!$E$6-Parameter!$E$7)+P6 -> 116.95386 | J6: =SUMPRODUCT((A_FINF*A_FINV+(1-A_FINF)*ROUNDUP((A_VERB/(A_LUO+(A_LUO=0)*$B6)+(A_MBLG>A_VERB/(A_LUO+(A_LUO=0)*$B6))*(A_MBLG-A_VERB/(A_LUO+(A_LUO=0)*$B6)))/A_MPG_E,0)*A_MPG_E)*A_PREIS) -> 11203695 | K6: =J6-$J$5 -> 7752649.1 | L6: =(M6+N6+O6+P6)-($M$5+$N$5+$O$5+$P$5) -> 116.03927 | M6: =SUMPRODUCT((A_LIFT=1)*((A_FACH>0)*A_FACH*(1+(A_KAPR>0)*((A_FINF*A_FINV+(1-A_FINF)*ROUNDUP((A_VERB/(A_LUO+(A_LUO=0)*$B6)+(A_MBLG>A_VERB/(A_LUO+(A_LUO=0)*$B6))*(A_MBLG-A_VERB/(A_LUO+(A_LUO=0)*$B6)))/A_MPG_E,0)*A_MPG_E)>A_KAPR)*((A_FINF*A_FINV+(1-A_FINF)*ROUNDUP((A_VERB/(A_LUO+(A_LUO=0)*$B6)+(A_MBLG>A_VERB/(A_LUO+(A_LUO=0)*$B6))*(A_MBLG-A_VERB/(A_LUO+(A_LUO=0)*$B6)))/A_MPG_E,0)*A_MPG_E)/(A_KAPR+(A_KAPR=0))-1))+(A_FACH=0)*((1-A_LOSE)*(A_GPT>0)*(A_FINF*A_FINN+(1-A_FINF)*ROUNDUP((A_VERB/(A_LUO+(A_LUO=0)*$B6)+(A_MBLG>A_VERB/(A_LUO+(A_LUO=0)*$B6))*(A_MBLG-A_VERB/(A_LUO+(A_LUO=0)*$B6)))/A_MPG_E,0))/(A_GPT+(A_GPT=0))+A_LOSE*((A_FINF*A_FINN+(1-A_FINF)*ROUNDUP((A_VERB/(A_LUO+(A_LUO=0)*$B6)+(A_MBLG>A_VERB/(A_LUO+(A_LUO=0)*$B6))*(A_MBLG-A_VERB/(A_LUO+(A_LUO=0)*$B6)))/A_MPG_E,0))>0)*A_LA*(1+(A_IST>0)*((A_FINF*A_FINN+(1-A_FINF)*ROUNDUP((A_VERB/(A_LUO+(A_LUO=0)*$B6)+(A_MBLG>A_VERB/(A_LUO+(A_LUO=0)*$B6))*(A_MBLG-A_VERB/(A_LUO+(A_LUO=0)*$B6)))/A_MPG_E,0))>A_IST)*((A_FINF*A_FINN+(1-A_FINF)*ROUNDUP((A_VERB/(A_LUO+(A_LUO=0)*$B6)+(A_MBLG>A_VERB/(A_LUO+(A_LUO=0)*$B6))*(A_MBLG-A_VERB/(A_LUO+(A_LUO=0)*$B6)))/A_MPG_E,0))/(A_IST+(A_IST=0))-1)))/MAX(0.1,N(Parameter!$M$21)))) -> 103.5356 | N6: =SUMPRODUCT((A_LIFT=2)*((A_FACH>0)*A_FACH*(1+(A_KAPR>0)*((A_FINF*A_FINV+(1-A_FINF)*ROUNDUP((A_VERB/(A_LUO+(A_LUO=0)*$B6)+(A_MBLG>A_VERB/(A_LUO+(A_LUO=0)*$B6))*(A_MBLG-A_VERB/(A_LUO+(A_LUO=0)*$B6)))/A_MPG_E,0)*A_MPG_E)>A_KAPR)*((A_FINF*A_FINV+(1-A_FINF)*ROUNDUP((A_VERB/(A_LUO+(A_LUO=0)*$B6)+(A_MBLG>A_VERB/(A_LUO+(A_LUO=0)*$B6))*(A_MBLG-A_VERB/(A_LUO+(A_LUO=0)*$B6)))/A_MPG_E,0)*A_MPG_E)/(A_KAPR+(A_KAPR=0))-1))+(A_FACH=0)*((1-A_LOSE)*(A_GPT>0)*(A_FINF*A_FINN+(1-A_FINF)*ROUNDUP((A_VERB/(A_LUO+(A_LUO=0)*$B6)+(A_MBLG>A_VERB/(A_LUO+(A_LUO=0)*$B6))*(A_MBLG-A_VERB/(A_LUO+(A_LUO=0)*$B6)))/A_MPG_E,0))/(A_GPT+(A_GPT=0))+A_LOSE*((A_FINF*A_FINN+(1-A_FINF)*ROUNDUP((A_VERB/(A_LUO+(A_LUO=0)*$B6)+(A_MBLG>A_VERB/(A_LUO+(A_LUO=0)*$B6))*(A_MBLG-A_VERB/(A_LUO+(A_LUO=0)*$B6)))/A_MPG_E,0))>0)*A_LA*(1+(A_IST>0)*((A_FINF*A_FINN+(1-A_FINF)*ROUNDUP((A_VERB/(A_LUO+(A_LUO=0)*$B6)+(A_MBLG>A_VERB/(A_LUO+(A_LUO=0)*$B6))*(A_MBLG-A_VERB/(A_LUO+(A_LUO=0)*$B6)))/A_MPG_E,0))>A_IST)*((A_FINF*A_FINN+(1-A_FINF)*ROUNDUP((A_VERB/(A_LUO+(A_LUO=0)*$B6)+(A_MBLG>A_VERB/(A_LUO+(A_LUO=0)*$B6))*(A_MBLG-A_VERB/(A_LUO+(A_LUO=0)*$B6)))/A_MPG_E,0))/(A_IST+(A_IST=0))-1)))/MAX(0.1,N(Parameter!$M$21)))) -> 122.84091 | O6: =SUMPRODUCT((A_LIFT=3)*((A_FACH>0)*A_FACH*(1+(A_KAPR>0)*((A_FINF*A_FINV+(1-A_FINF)*ROUNDUP((A_VERB/(A_LUO+(A_LUO=0)*$B6)+(A_MBLG>A_VERB/(A_LUO+(A_LUO=0)*$B6))*(A_MBLG-A_VERB/(A_LUO+(A_LUO=0)*$B6)))/A_MPG_E,0)*A_MPG_E)>A_KAPR)*((A_FINF*A_FINV+(1-A_FINF)*ROUNDUP((A_VERB/(A_LUO+(A_LUO=0)*$B6)+(A_MBLG>A_VERB/(A_LUO+(A_LUO=0)*$B6))*(A_MBLG-A_VERB/(A_LUO+(A_LUO=0)*$B6)))/A_MPG_E,0)*A_MPG_E)/(A_KAPR+(A_KAPR=0))-1))+(A_FACH=0)*((1-A_LOSE)*(A_GPT>0)*(A_FINF*A_FINN+(1-A_FINF)*ROUNDUP((A_VERB/(A_LUO+(A_LUO=0)*$B6)+(A_MBLG>A_VERB/(A_LUO+(A_LUO=0)*$B6))*(A_MBLG-A_VERB/(A_LUO+(A_LUO=0)*$B6)))/A_MPG_E,0))/(A_GPT+(A_GPT=0))+A_LOSE*((A_FINF*A_FINN+(1-A_FINF)*ROUNDUP((A_VERB/(A_LUO+(A_LUO=0)*$B6)+(A_MBLG>A_VERB/(A_LUO+(A_LUO=0)*$B6))*(A_MBLG-A_VERB/(A_LUO+(A_LUO=0)*$B6)))/A_MPG_E,0))>0)*A_LA*(1+(A_IST>0)*((A_FINF*A_FINN+(1-A_FINF)*ROUNDUP((A_VERB/(A_LUO+(A_LUO=0)*$B6)+(A_MBLG>A_VERB/(A_LUO+(A_LUO=0)*$B6))*(A_MBLG-A_VERB/(A_LUO+(A_LUO=0)*$B6)))/A_MPG_E,0))>A_IST)*((A_FINF*A_FINN+(1-A_FINF)*ROUNDUP((A_VERB/(A_LUO+(A_LUO=0)*$B6)+(A_MBLG>A_VERB/(A_LUO+(A_LUO=0)*$B6))*(A_MBLG-A_VERB/(A_LUO+(A_LUO=0)*$B6)))/A_MPG_E,0))/(A_IST+(A_IST=0))-1)))/MAX(0.1,N(Parameter!$M$21)))) -> 40.577345 | P6: =SUMPRODUCT((A_LIFT="Aussen")*((A_FACH>0)*A_FACH*(1+(A_KAPR>0)*((A_FINF*A_FINV+(1-A_FINF)*ROUNDUP((A_VERB/(A_LUO+(A_LUO=0)*$B6)+(A_MBLG>A_VERB/(A_LUO+(A_LUO=0)*$B6))*(A_MBLG-A_VERB/(A_LUO+(A_LUO=0)*$B6)))/A_MPG_E,0)*A_MPG_E)>A_KAPR)*((A_FINF*A_FINV+(1-A_FINF)*ROUNDUP((A_VERB/(A_LUO+(A_LUO=0)*$B6)+(A_MBLG>A_VERB/(A_LUO+(A_LUO=0)*$B6))*(A_MBLG-A_VERB/(A_LUO+(A_LUO=0)*$B6)))/A_MPG_E,0)*A_MPG_E)/(A_KAPR+(A_KAPR=0))-1))+(A_FACH=0)*((1-A_LOSE)*(A_GPT>0)*(A_FINF*A_FINN+(1-A_FINF)*ROUNDUP((A_VERB/(A_LUO+(A_LUO=0)*$B6)+(A_MBLG>A_VERB/(A_LUO+(A_LUO=0)*$B6))*(A_MBLG-A_VERB/(A_LUO+(A_LUO=0)*$B6)))/A_MPG_E,0))/(A_GPT+(A_GPT=0))+A_LOSE*((A_FINF*A_FINN+(1-A_FINF)*ROUNDUP((A_VERB/(A_LUO+(A_LUO=0)*$B6)+(A_MBLG>A_VERB/(A_LUO+(A_LUO=0)*$B6))*(A_MBLG-A_VERB/(A_LUO+(A_LUO=0)*$B6)))/A_MPG_E,0))>0)*A_LA*(1+(A_IST>0)*((A_FINF*A_FINN+(1-A_FINF)*ROUNDUP((A_VERB/(A_LUO+(A_LUO=0)*$B6)+(A_MBLG>A_VERB/(A_LUO+(A_LUO=0)*$B6))*(A_MBLG-A_VERB/(A_LUO+(A_LUO=0)*$B6)))/A_MPG_E,0))>A_IST)*((A_FINF*A_FINN+(1-A_FINF)*ROUNDUP((A_VERB/(A_LUO+(A_LUO=0)*$B6)+(A_MBLG>A_VERB/(A_LUO+(A_LUO=0)*$B6))*(A_MBLG-A_VERB/(A_LUO+(A_LUO=0)*$B6)))/A_MPG_E,0))/(A_IST+(A_IST=0))-1)))/MAX(0.1,N(Parameter!$M$21)))) -> 0
A7: B – Ziel-LU | B7: =Parameter!$A$24 -> 1.5 | C7: =M7/Parameter!$E$5 -> 1.6096133 | D7: =N7/Parameter!$E$6 -> 2.0284848 | E7: =O7/Parameter!$E$7 -> 0.73998514 | F7: =(N7+O7)/(Parameter!$E$6+Parameter!$E$7) -> 1.384235 | G7: =(M7+N7+O7)/Parameter!$E$8 -> 1.4593611 | H7: =IF(AND(M7<=Parameter!$E$5,N7+O7<=Parameter!$E$6+Parameter!$E$7),"JA","NEIN") -> NEIN | I7: =MAX(0,M7-Parameter!$E$5)+MAX(0,N7+O7-Parameter!$E$6-Parameter!$E$7)+P7 -> 68.904163 | J7: =SUMPRODUCT((A_FINF*A_FINV+(1-A_FINF)*ROUNDUP((A_VERB/(A_LUO+(A_LUO=0)*$B7)+(A_MBLG>A_VERB/(A_LUO+(A_LUO=0)*$B7))*(A_MBLG-A_VERB/(A_LUO+(A_LUO=0)*$B7)))/A_MPG_E,0)*A_MPG_E)*A_PREIS) -> 8790985.1 | K7: =J7-$J$5 -> 5339938.9 | L7: =(M7+N7+O7+P7)-($M$5+$N$5+$O$5+$P$5) -> 67.989574 | M7: =SUMPRODUCT((A_LIFT=1)*((A_FACH>0)*A_FACH*(1+(A_KAPR>0)*((A_FINF*A_FINV+(1-A_FINF)*ROUNDUP((A_VERB/(A_LUO+(A_LUO=0)*$B7)+(A_MBLG>A_VERB/(A_LUO+(A_LUO=0)*$B7))*(A_MBLG-A_VERB/(A_LUO+(A_LUO=0)*$B7)))/A_MPG_E,0)*A_MPG_E)>A_KAPR)*((A_FINF*A_FINV+(1-A_FINF)*ROUNDUP((A_VERB/(A_LUO+(A_LUO=0)*$B7)+(A_MBLG>A_VERB/(A_LUO+(A_LUO=0)*$B7))*(A_MBLG-A_VERB/(A_LUO+(A_LUO=0)*$B7)))/A_MPG_E,0)*A_MPG_E)/(A_KAPR+(A_KAPR=0))-1))+(A_FACH=0)*((1-A_LOSE)*(A_GPT>0)*(A_FINF*A_FINN+(1-A_FINF)*ROUNDUP((A_VERB/(A_LUO+(A_LUO=0)*$B7)+(A_MBLG>A_VERB/(A_LUO+(A_LUO=0)*$B7))*(A_MBLG-A_VERB/(A_LUO+(A_LUO=0)*$B7)))/A_MPG_E,0))/(A_GPT+(A_GPT=0))+A_LOSE*((A_FINF*A_FINN+(1-A_FINF)*ROUNDUP((A_VERB/(A_LUO+(A_LUO=0)*$B7)+(A_MBLG>A_VERB/(A_LUO+(A_LUO=0)*$B7))*(A_MBLG-A_VERB/(A_LUO+(A_LUO=0)*$B7)))/A_MPG_E,0))>0)*A_LA*(1+(A_IST>0)*((A_FINF*A_FINN+(1-A_FINF)*ROUNDUP((A_VERB/(A_LUO+(A_LUO=0)*$B7)+(A_MBLG>A_VERB/(A_LUO+(A_LUO=0)*$B7))*(A_MBLG-A_VERB/(A_LUO+(A_LUO=0)*$B7)))/A_MPG_E,0))>A_IST)*((A_FINF*A_FINN+(1-A_FINF)*ROUNDUP((A_VERB/(A_LUO+(A_LUO=0)*$B7)+(A_MBLG>A_VERB/(A_LUO+(A_LUO=0)*$B7))*(A_MBLG-A_VERB/(A_LUO+(A_LUO=0)*$B7)))/A_MPG_E,0))/(A_IST+(A_IST=0))-1)))/MAX(0.1,N(Parameter!$M$21)))) -> 80.480664 | N7: =SUMPRODUCT((A_LIFT=2)*((A_FACH>0)*A_FACH*(1+(A_KAPR>0)*((A_FINF*A_FINV+(1-A_FINF)*ROUNDUP((A_VERB/(A_LUO+(A_LUO=0)*$B7)+(A_MBLG>A_VERB/(A_LUO+(A_LUO=0)*$B7))*(A_MBLG-A_VERB/(A_LUO+(A_LUO=0)*$B7)))/A_MPG_E,0)*A_MPG_E)>A_KAPR)*((A_FINF*A_FINV+(1-A_FINF)*ROUNDUP((A_VERB/(A_LUO+(A_LUO=0)*$B7)+(A_MBLG>A_VERB/(A_LUO+(A_LUO=0)*$B7))*(A_MBLG-A_VERB/(A_LUO+(A_LUO=0)*$B7)))/A_MPG_E,0)*A_MPG_E)/(A_KAPR+(A_KAPR=0))-1))+(A_FACH=0)*((1-A_LOSE)*(A_GPT>0)*(A_FINF*A_FINN+(1-A_FINF)*ROUNDUP((A_VERB/(A_LUO+(A_LUO=0)*$B7)+(A_MBLG>A_VERB/(A_LUO+(A_LUO=0)*$B7))*(A_MBLG-A_VERB/(A_LUO+(A_LUO=0)*$B7)))/A_MPG_E,0))/(A_GPT+(A_GPT=0))+A_LOSE*((A_FINF*A_FINN+(1-A_FINF)*ROUNDUP((A_VERB/(A_LUO+(A_LUO=0)*$B7)+(A_MBLG>A_VERB/(A_LUO+(A_LUO=0)*$B7))*(A_MBLG-A_VERB/(A_LUO+(A_LUO=0)*$B7)))/A_MPG_E,0))>0)*A_LA*(1+(A_IST>0)*((A_FINF*A_FINN+(1-A_FINF)*ROUNDUP((A_VERB/(A_LUO+(A_LUO=0)*$B7)+(A_MBLG>A_VERB/(A_LUO+(A_LUO=0)*$B7))*(A_MBLG-A_VERB/(A_LUO+(A_LUO=0)*$B7)))/A_MPG_E,0))>A_IST)*((A_FINF*A_FINN+(1-A_FINF)*ROUNDUP((A_VERB/(A_LUO+(A_LUO=0)*$B7)+(A_MBLG>A_VERB/(A_LUO+(A_LUO=0)*$B7))*(A_MBLG-A_VERB/(A_LUO+(A_LUO=0)*$B7)))/A_MPG_E,0))/(A_IST+(A_IST=0))-1)))/MAX(0.1,N(Parameter!$M$21)))) -> 101.42424 | O7: =SUMPRODUCT((A_LIFT=3)*((A_FACH>0)*A_FACH*(1+(A_KAPR>0)*((A_FINF*A_FINV+(1-A_FINF)*ROUNDUP((A_VERB/(A_LUO+(A_LUO=0)*$B7)+(A_MBLG>A_VERB/(A_LUO+(A_LUO=0)*$B7))*(A_MBLG-A_VERB/(A_LUO+(A_LUO=0)*$B7)))/A_MPG_E,0)*A_MPG_E)>A_KAPR)*((A_FINF*A_FINV+(1-A_FINF)*ROUNDUP((A_VERB/(A_LUO+(A_LUO=0)*$B7)+(A_MBLG>A_VERB/(A_LUO+(A_LUO=0)*$B7))*(A_MBLG-A_VERB/(A_LUO+(A_LUO=0)*$B7)))/A_MPG_E,0)*A_MPG_E)/(A_KAPR+(A_KAPR=0))-1))+(A_FACH=0)*((1-A_LOSE)*(A_GPT>0)*(A_FINF*A_FINN+(1-A_FINF)*ROUNDUP((A_VERB/(A_LUO+(A_LUO=0)*$B7)+(A_MBLG>A_VERB/(A_LUO+(A_LUO=0)*$B7))*(A_MBLG-A_VERB/(A_LUO+(A_LUO=0)*$B7)))/A_MPG_E,0))/(A_GPT+(A_GPT=0))+A_LOSE*((A_FINF*A_FINN+(1-A_FINF)*ROUNDUP((A_VERB/(A_LUO+(A_LUO=0)*$B7)+(A_MBLG>A_VERB/(A_LUO+(A_LUO=0)*$B7))*(A_MBLG-A_VERB/(A_LUO+(A_LUO=0)*$B7)))/A_MPG_E,0))>0)*A_LA*(1+(A_IST>0)*((A_FINF*A_FINN+(1-A_FINF)*ROUNDUP((A_VERB/(A_LUO+(A_LUO=0)*$B7)+(A_MBLG>A_VERB/(A_LUO+(A_LUO=0)*$B7))*(A_MBLG-A_VERB/(A_LUO+(A_LUO=0)*$B7)))/A_MPG_E,0))>A_IST)*((A_FINF*A_FINN+(1-A_FINF)*ROUNDUP((A_VERB/(A_LUO+(A_LUO=0)*$B7)+(A_MBLG>A_VERB/(A_LUO+(A_LUO=0)*$B7))*(A_MBLG-A_VERB/(A_LUO+(A_LUO=0)*$B7)))/A_MPG_E,0))/(A_IST+(A_IST=0))-1)))/MAX(0.1,N(Parameter!$M$21)))) -> 36.999257 | P7: =SUMPRODUCT((A_LIFT="Aussen")*((A_FACH>0)*A_FACH*(1+(A_KAPR>0)*((A_FINF*A_FINV+(1-A_FINF)*ROUNDUP((A_VERB/(A_LUO+(A_LUO=0)*$B7)+(A_MBLG>A_VERB/(A_LUO+(A_LUO=0)*$B7))*(A_MBLG-A_VERB/(A_LUO+(A_LUO=0)*$B7)))/A_MPG_E,0)*A_MPG_E)>A_KAPR)*((A_FINF*A_FINV+(1-A_FINF)*ROUNDUP((A_VERB/(A_LUO+(A_LUO=0)*$B7)+(A_MBLG>A_VERB/(A_LUO+(A_LUO=0)*$B7))*(A_MBLG-A_VERB/(A_LUO+(A_LUO=0)*$B7)))/A_MPG_E,0)*A_MPG_E)/(A_KAPR+(A_KAPR=0))-1))+(A_FACH=0)*((1-A_LOSE)*(A_GPT>0)*(A_FINF*A_FINN+(1-A_FINF)*ROUNDUP((A_VERB/(A_LUO+(A_LUO=0)*$B7)+(A_MBLG>A_VERB/(A_LUO+(A_LUO=0)*$B7))*(A_MBLG-A_VERB/(A_LUO+(A_LUO=0)*$B7)))/A_MPG_E,0))/(A_GPT+(A_GPT=0))+A_LOSE*((A_FINF*A_FINN+(1-A_FINF)*ROUNDUP((A_VERB/(A_LUO+(A_LUO=0)*$B7)+(A_MBLG>A_VERB/(A_LUO+(A_LUO=0)*$B7))*(A_MBLG-A_VERB/(A_LUO+(A_LUO=0)*$B7)))/A_MPG_E,0))>0)*A_LA*(1+(A_IST>0)*((A_FINF*A_FINN+(1-A_FINF)*ROUNDUP((A_VERB/(A_LUO+(A_LUO=0)*$B7)+(A_MBLG>A_VERB/(A_LUO+(A_LUO=0)*$B7))*(A_MBLG-A_VERB/(A_LUO+(A_LUO=0)*$B7)))/A_MPG_E,0))>A_IST)*((A_FINF*A_FINN+(1-A_FINF)*ROUNDUP((A_VERB/(A_LUO+(A_LUO=0)*$B7)+(A_MBLG>A_VERB/(A_LUO+(A_LUO=0)*$B7))*(A_MBLG-A_VERB/(A_LUO+(A_LUO=0)*$B7)))/A_MPG_E,0))/(A_IST+(A_IST=0))-1)))/MAX(0.1,N(Parameter!$M$21)))) -> 0
A8: B – Ziel-LU | B8: =Parameter!$A$25 -> 2 | C8: =M8/Parameter!$E$5 -> 1.409861 | D8: =N8/Parameter!$E$6 -> 1.8051515 | E8: =O8/Parameter!$E$7 -> 0.71012888 | F8: =(N8+O8)/(Parameter!$E$6+Parameter!$E$7) -> 1.2576402 | G8: =(M8+N8+O8)/Parameter!$E$8 -> 1.3083805 | H8: =IF(AND(M8<=Parameter!$E$5,N8+O8<=Parameter!$E$6+Parameter!$E$7),"JA","NEIN") -> NEIN | I8: =MAX(0,M8-Parameter!$E$5)+MAX(0,N8+O8-Parameter!$E$6-Parameter!$E$7)+P8 -> 46.257069 | J8: =SUMPRODUCT((A_FINF*A_FINV+(1-A_FINF)*ROUNDUP((A_VERB/(A_LUO+(A_LUO=0)*$B8)+(A_MBLG>A_VERB/(A_LUO+(A_LUO=0)*$B8))*(A_MBLG-A_VERB/(A_LUO+(A_LUO=0)*$B8)))/A_MPG_E,0)*A_MPG_E)*A_PREIS) -> 7548386.4 | K8: =J8-$J$5 -> 4097340.2 | L8: =(M8+N8+O8+P8)-($M$5+$N$5+$O$5+$P$5) -> 45.34248 | M8: =SUMPRODUCT((A_LIFT=1)*((A_FACH>0)*A_FACH*(1+(A_KAPR>0)*((A_FINF*A_FINV+(1-A_FINF)*ROUNDUP((A_VERB/(A_LUO+(A_LUO=0)*$B8)+(A_MBLG>A_VERB/(A_LUO+(A_LUO=0)*$B8))*(A_MBLG-A_VERB/(A_LUO+(A_LUO=0)*$B8)))/A_MPG_E,0)*A_MPG_E)>A_KAPR)*((A_FINF*A_FINV+(1-A_FINF)*ROUNDUP((A_VERB/(A_LUO+(A_LUO=0)*$B8)+(A_MBLG>A_VERB/(A_LUO+(A_LUO=0)*$B8))*(A_MBLG-A_VERB/(A_LUO+(A_LUO=0)*$B8)))/A_MPG_E,0)*A_MPG_E)/(A_KAPR+(A_KAPR=0))-1))+(A_FACH=0)*((1-A_LOSE)*(A_GPT>0)*(A_FINF*A_FINN+(1-A_FINF)*ROUNDUP((A_VERB/(A_LUO+(A_LUO=0)*$B8)+(A_MBLG>A_VERB/(A_LUO+(A_LUO=0)*$B8))*(A_MBLG-A_VERB/(A_LUO+(A_LUO=0)*$B8)))/A_MPG_E,0))/(A_GPT+(A_GPT=0))+A_LOSE*((A_FINF*A_FINN+(1-A_FINF)*ROUNDUP((A_VERB/(A_LUO+(A_LUO=0)*$B8)+(A_MBLG>A_VERB/(A_LUO+(A_LUO=0)*$B8))*(A_MBLG-A_VERB/(A_LUO+(A_LUO=0)*$B8)))/A_MPG_E,0))>0)*A_LA*(1+(A_IST>0)*((A_FINF*A_FINN+(1-A_FINF)*ROUNDUP((A_VERB/(A_LUO+(A_LUO=0)*$B8)+(A_MBLG>A_VERB/(A_LUO+(A_LUO=0)*$B8))*(A_MBLG-A_VERB/(A_LUO+(A_LUO=0)*$B8)))/A_MPG_E,0))>A_IST)*((A_FINF*A_FINN+(1-A_FINF)*ROUNDUP((A_VERB/(A_LUO+(A_LUO=0)*$B8)+(A_MBLG>A_VERB/(A_LUO+(A_LUO=0)*$B8))*(A_MBLG-A_VERB/(A_LUO+(A_LUO=0)*$B8)))/A_MPG_E,0))/(A_IST+(A_IST=0))-1)))/MAX(0.1,N(Parameter!$M$21)))) -> 70.49305 | N8: =SUMPRODUCT((A_LIFT=2)*((A_FACH>0)*A_FACH*(1+(A_KAPR>0)*((A_FINF*A_FINV+(1-A_FINF)*ROUNDUP((A_VERB/(A_LUO+(A_LUO=0)*$B8)+(A_MBLG>A_VERB/(A_LUO+(A_LUO=0)*$B8))*(A_MBLG-A_VERB/(A_LUO+(A_LUO=0)*$B8)))/A_MPG_E,0)*A_MPG_E)>A_KAPR)*((A_FINF*A_FINV+(1-A_FINF)*ROUNDUP((A_VERB/(A_LUO+(A_LUO=0)*$B8)+(A_MBLG>A_VERB/(A_LUO+(A_LUO=0)*$B8))*(A_MBLG-A_VERB/(A_LUO+(A_LUO=0)*$B8)))/A_MPG_E,0)*A_MPG_E)/(A_KAPR+(A_KAPR=0))-1))+(A_FACH=0)*((1-A_LOSE)*(A_GPT>0)*(A_FINF*A_FINN+(1-A_FINF)*ROUNDUP((A_VERB/(A_LUO+(A_LUO=0)*$B8)+(A_MBLG>A_VERB/(A_LUO+(A_LUO=0)*$B8))*(A_MBLG-A_VERB/(A_LUO+(A_LUO=0)*$B8)))/A_MPG_E,0))/(A_GPT+(A_GPT=0))+A_LOSE*((A_FINF*A_FINN+(1-A_FINF)*ROUNDUP((A_VERB/(A_LUO+(A_LUO=0)*$B8)+(A_MBLG>A_VERB/(A_LUO+(A_LUO=0)*$B8))*(A_MBLG-A_VERB/(A_LUO+(A_LUO=0)*$B8)))/A_MPG_E,0))>0)*A_LA*(1+(A_IST>0)*((A_FINF*A_FINN+(1-A_FINF)*ROUNDUP((A_VERB/(A_LUO+(A_LUO=0)*$B8)+(A_MBLG>A_VERB/(A_LUO+(A_LUO=0)*$B8))*(A_MBLG-A_VERB/(A_LUO+(A_LUO=0)*$B8)))/A_MPG_E,0))>A_IST)*((A_FINF*A_FINN+(1-A_FINF)*ROUNDUP((A_VERB/(A_LUO+(A_LUO=0)*$B8)+(A_MBLG>A_VERB/(A_LUO+(A_LUO=0)*$B8))*(A_MBLG-A_VERB/(A_LUO+(A_LUO=0)*$B8)))/A_MPG_E,0))/(A_IST+(A_IST=0))-1)))/MAX(0.1,N(Parameter!$M$21)))) -> 90.257576 | O8: =SUMPRODUCT((A_LIFT=3)*((A_FACH>0)*A_FACH*(1+(A_KAPR>0)*((A_FINF*A_FINV+(1-A_FINF)*ROUNDUP((A_VERB/(A_LUO+(A_LUO=0)*$B8)+(A_MBLG>A_VERB/(A_LUO+(A_LUO=0)*$B8))*(A_MBLG-A_VERB/(A_LUO+(A_LUO=0)*$B8)))/A_MPG_E,0)*A_MPG_E)>A_KAPR)*((A_FINF*A_FINV+(1-A_FINF)*ROUNDUP((A_VERB/(A_LUO+(A_LUO=0)*$B8)+(A_MBLG>A_VERB/(A_LUO+(A_LUO=0)*$B8))*(A_MBLG-A_VERB/(A_LUO+(A_LUO=0)*$B8)))/A_MPG_E,0)*A_MPG_E)/(A_KAPR+(A_KAPR=0))-1))+(A_FACH=0)*((1-A_LOSE)*(A_GPT>0)*(A_FINF*A_FINN+(1-A_FINF)*ROUNDUP((A_VERB/(A_LUO+(A_LUO=0)*$B8)+(A_MBLG>A_VERB/(A_LUO+(A_LUO=0)*$B8))*(A_MBLG-A_VERB/(A_LUO+(A_LUO=0)*$B8)))/A_MPG_E,0))/(A_GPT+(A_GPT=0))+A_LOSE*((A_FINF*A_FINN+(1-A_FINF)*ROUNDUP((A_VERB/(A_LUO+(A_LUO=0)*$B8)+(A_MBLG>A_VERB/(A_LUO+(A_LUO=0)*$B8))*(A_MBLG-A_VERB/(A_LUO+(A_LUO=0)*$B8)))/A_MPG_E,0))>0)*A_LA*(1+(A_IST>0)*((A_FINF*A_FINN+(1-A_FINF)*ROUNDUP((A_VERB/(A_LUO+(A_LUO=0)*$B8)+(A_MBLG>A_VERB/(A_LUO+(A_LUO=0)*$B8))*(A_MBLG-A_VERB/(A_LUO+(A_LUO=0)*$B8)))/A_MPG_E,0))>A_IST)*((A_FINF*A_FINN+(1-A_FINF)*ROUNDUP((A_VERB/(A_LUO+(A_LUO=0)*$B8)+(A_MBLG>A_VERB/(A_LUO+(A_LUO=0)*$B8))*(A_MBLG-A_VERB/(A_LUO+(A_LUO=0)*$B8)))/A_MPG_E,0))/(A_IST+(A_IST=0))-1)))/MAX(0.1,N(Parameter!$M$21)))) -> 35.506444 | P8: =SUMPRODUCT((A_LIFT="Aussen")*((A_FACH>0)*A_FACH*(1+(A_KAPR>0)*((A_FINF*A_FINV+(1-A_FINF)*ROUNDUP((A_VERB/(A_LUO+(A_LUO=0)*$B8)+(A_MBLG>A_VERB/(A_LUO+(A_LUO=0)*$B8))*(A_MBLG-A_VERB/(A_LUO+(A_LUO=0)*$B8)))/A_MPG_E,0)*A_MPG_E)>A_KAPR)*((A_FINF*A_FINV+(1-A_FINF)*ROUNDUP((A_VERB/(A_LUO+(A_LUO=0)*$B8)+(A_MBLG>A_VERB/(A_LUO+(A_LUO=0)*$B8))*(A_MBLG-A_VERB/(A_LUO+(A_LUO=0)*$B8)))/A_MPG_E,0)*A_MPG_E)/(A_KAPR+(A_KAPR=0))-1))+(A_FACH=0)*((1-A_LOSE)*(A_GPT>0)*(A_FINF*A_FINN+(1-A_FINF)*ROUNDUP((A_VERB/(A_LUO+(A_LUO=0)*$B8)+(A_MBLG>A_VERB/(A_LUO+(A_LUO=0)*$B8))*(A_MBLG-A_VERB/(A_LUO+(A_LUO=0)*$B8)))/A_MPG_E,0))/(A_GPT+(A_GPT=0))+A_LOSE*((A_FINF*A_FINN+(1-A_FINF)*ROUNDUP((A_VERB/(A_LUO+(A_LUO=0)*$B8)+(A_MBLG>A_VERB/(A_LUO+(A_LUO=0)*$B8))*(A_MBLG-A_VERB/(A_LUO+(A_LUO=0)*$B8)))/A_MPG_E,0))>0)*A_LA*(1+(A_IST>0)*((A_FINF*A_FINN+(1-A_FINF)*ROUNDUP((A_VERB/(A_LUO+(A_LUO=0)*$B8)+(A_MBLG>A_VERB/(A_LUO+(A_LUO=0)*$B8))*(A_MBLG-A_VERB/(A_LUO+(A_LUO=0)*$B8)))/A_MPG_E,0))>A_IST)*((A_FINF*A_FINN+(1-A_FINF)*ROUNDUP((A_VERB/(A_LUO+(A_LUO=0)*$B8)+(A_MBLG>A_VERB/(A_LUO+(A_LUO=0)*$B8))*(A_MBLG-A_VERB/(A_LUO+(A_LUO=0)*$B8)))/A_MPG_E,0))/(A_IST+(A_IST=0))-1)))/MAX(0.1,N(Parameter!$M$21)))) -> 0
A9: B – Ziel-LU | B9: =Parameter!$A$26 -> 2.5 | C9: =M9/Parameter!$E$5 -> 1.3310033 | D9: =N9/Parameter!$E$6 -> 1.7118182 | E9: =O9/Parameter!$E$7 -> 0.69666734 | F9: =(N9+O9)/(Parameter!$E$6+Parameter!$E$7) -> 1.2042428 | G9: =(M9+N9+O9)/Parameter!$E$8 -> 1.2464963 | H9: =IF(AND(M9<=Parameter!$E$5,N9+O9<=Parameter!$E$6+Parameter!$E$7),"JA","NEIN") -> NEIN | I9: =MAX(0,M9-Parameter!$E$5)+MAX(0,N9+O9-Parameter!$E$6-Parameter!$E$7)+P9 -> 36.974439 | J9: =SUMPRODUCT((A_FINF*A_FINV+(1-A_FINF)*ROUNDUP((A_VERB/(A_LUO+(A_LUO=0)*$B9)+(A_MBLG>A_VERB/(A_LUO+(A_LUO=0)*$B9))*(A_MBLG-A_VERB/(A_LUO+(A_LUO=0)*$B9)))/A_MPG_E,0)*A_MPG_E)*A_PREIS) -> 6973175.7 | K9: =J9-$J$5 -> 3522129.5 | L9: =(M9+N9+O9+P9)-($M$5+$N$5+$O$5+$P$5) -> 36.05985 | M9: =SUMPRODUCT((A_LIFT=1)*((A_FACH>0)*A_FACH*(1+(A_KAPR>0)*((A_FINF*A_FINV+(1-A_FINF)*ROUNDUP((A_VERB/(A_LUO+(A_LUO=0)*$B9)+(A_MBLG>A_VERB/(A_LUO+(A_LUO=0)*$B9))*(A_MBLG-A_VERB/(A_LUO+(A_LUO=0)*$B9)))/A_MPG_E,0)*A_MPG_E)>A_KAPR)*((A_FINF*A_FINV+(1-A_FINF)*ROUNDUP((A_VERB/(A_LUO+(A_LUO=0)*$B9)+(A_MBLG>A_VERB/(A_LUO+(A_LUO=0)*$B9))*(A_MBLG-A_VERB/(A_LUO+(A_LUO=0)*$B9)))/A_MPG_E,0)*A_MPG_E)/(A_KAPR+(A_KAPR=0))-1))+(A_FACH=0)*((1-A_LOSE)*(A_GPT>0)*(A_FINF*A_FINN+(1-A_FINF)*ROUNDUP((A_VERB/(A_LUO+(A_LUO=0)*$B9)+(A_MBLG>A_VERB/(A_LUO+(A_LUO=0)*$B9))*(A_MBLG-A_VERB/(A_LUO+(A_LUO=0)*$B9)))/A_MPG_E,0))/(A_GPT+(A_GPT=0))+A_LOSE*((A_FINF*A_FINN+(1-A_FINF)*ROUNDUP((A_VERB/(A_LUO+(A_LUO=0)*$B9)+(A_MBLG>A_VERB/(A_LUO+(A_LUO=0)*$B9))*(A_MBLG-A_VERB/(A_LUO+(A_LUO=0)*$B9)))/A_MPG_E,0))>0)*A_LA*(1+(A_IST>0)*((A_FINF*A_FINN+(1-A_FINF)*ROUNDUP((A_VERB/(A_LUO+(A_LUO=0)*$B9)+(A_MBLG>A_VERB/(A_LUO+(A_LUO=0)*$B9))*(A_MBLG-A_VERB/(A_LUO+(A_LUO=0)*$B9)))/A_MPG_E,0))>A_IST)*((A_FINF*A_FINN+(1-A_FINF)*ROUNDUP((A_VERB/(A_LUO+(A_LUO=0)*$B9)+(A_MBLG>A_VERB/(A_LUO+(A_LUO=0)*$B9))*(A_MBLG-A_VERB/(A_LUO+(A_LUO=0)*$B9)))/A_MPG_E,0))/(A_IST+(A_IST=0))-1)))/MAX(0.1,N(Parameter!$M$21)))) -> 66.550163 | N9: =SUMPRODUCT((A_LIFT=2)*((A_FACH>0)*A_FACH*(1+(A_KAPR>0)*((A_FINF*A_FINV+(1-A_FINF)*ROUNDUP((A_VERB/(A_LUO+(A_LUO=0)*$B9)+(A_MBLG>A_VERB/(A_LUO+(A_LUO=0)*$B9))*(A_MBLG-A_VERB/(A_LUO+(A_LUO=0)*$B9)))/A_MPG_E,0)*A_MPG_E)>A_KAPR)*((A_FINF*A_FINV+(1-A_FINF)*ROUNDUP((A_VERB/(A_LUO+(A_LUO=0)*$B9)+(A_MBLG>A_VERB/(A_LUO+(A_LUO=0)*$B9))*(A_MBLG-A_VERB/(A_LUO+(A_LUO=0)*$B9)))/A_MPG_E,0)*A_MPG_E)/(A_KAPR+(A_KAPR=0))-1))+(A_FACH=0)*((1-A_LOSE)*(A_GPT>0)*(A_FINF*A_FINN+(1-A_FINF)*ROUNDUP((A_VERB/(A_LUO+(A_LUO=0)*$B9)+(A_MBLG>A_VERB/(A_LUO+(A_LUO=0)*$B9))*(A_MBLG-A_VERB/(A_LUO+(A_LUO=0)*$B9)))/A_MPG_E,0))/(A_GPT+(A_GPT=0))+A_LOSE*((A_FINF*A_FINN+(1-A_FINF)*ROUNDUP((A_VERB/(A_LUO+(A_LUO=0)*$B9)+(A_MBLG>A_VERB/(A_LUO+(A_LUO=0)*$B9))*(A_MBLG-A_VERB/(A_LUO+(A_LUO=0)*$B9)))/A_MPG_E,0))>0)*A_LA*(1+(A_IST>0)*((A_FINF*A_FINN+(1-A_FINF)*ROUNDUP((A_VERB/(A_LUO+(A_LUO=0)*$B9)+(A_MBLG>A_VERB/(A_LUO+(A_LUO=0)*$B9))*(A_MBLG-A_VERB/(A_LUO+(A_LUO=0)*$B9)))/A_MPG_E,0))>A_IST)*((A_FINF*A_FINN+(1-A_FINF)*ROUNDUP((A_VERB/(A_LUO+(A_LUO=0)*$B9)+(A_MBLG>A_VERB/(A_LUO+(A_LUO=0)*$B9))*(A_MBLG-A_VERB/(A_LUO+(A_LUO=0)*$B9)))/A_MPG_E,0))/(A_IST+(A_IST=0))-1)))/MAX(0.1,N(Parameter!$M$21)))) -> 85.590909 | O9: =SUMPRODUCT((A_LIFT=3)*((A_FACH>0)*A_FACH*(1+(A_KAPR>0)*((A_FINF*A_FINV+(1-A_FINF)*ROUNDUP((A_VERB/(A_LUO+(A_LUO=0)*$B9)+(A_MBLG>A_VERB/(A_LUO+(A_LUO=0)*$B9))*(A_MBLG-A_VERB/(A_LUO+(A_LUO=0)*$B9)))/A_MPG_E,0)*A_MPG_E)>A_KAPR)*((A_FINF*A_FINV+(1-A_FINF)*ROUNDUP((A_VERB/(A_LUO+(A_LUO=0)*$B9)+(A_MBLG>A_VERB/(A_LUO+(A_LUO=0)*$B9))*(A_MBLG-A_VERB/(A_LUO+(A_LUO=0)*$B9)))/A_MPG_E,0)*A_MPG_E)/(A_KAPR+(A_KAPR=0))-1))+(A_FACH=0)*((1-A_LOSE)*(A_GPT>0)*(A_FINF*A_FINN+(1-A_FINF)*ROUNDUP((A_VERB/(A_LUO+(A_LUO=0)*$B9)+(A_MBLG>A_VERB/(A_LUO+(A_LUO=0)*$B9))*(A_MBLG-A_VERB/(A_LUO+(A_LUO=0)*$B9)))/A_MPG_E,0))/(A_GPT+(A_GPT=0))+A_LOSE*((A_FINF*A_FINN+(1-A_FINF)*ROUNDUP((A_VERB/(A_LUO+(A_LUO=0)*$B9)+(A_MBLG>A_VERB/(A_LUO+(A_LUO=0)*$B9))*(A_MBLG-A_VERB/(A_LUO+(A_LUO=0)*$B9)))/A_MPG_E,0))>0)*A_LA*(1+(A_IST>0)*((A_FINF*A_FINN+(1-A_FINF)*ROUNDUP((A_VERB/(A_LUO+(A_LUO=0)*$B9)+(A_MBLG>A_VERB/(A_LUO+(A_LUO=0)*$B9))*(A_MBLG-A_VERB/(A_LUO+(A_LUO=0)*$B9)))/A_MPG_E,0))>A_IST)*((A_FINF*A_FINN+(1-A_FINF)*ROUNDUP((A_VERB/(A_LUO+(A_LUO=0)*$B9)+(A_MBLG>A_VERB/(A_LUO+(A_LUO=0)*$B9))*(A_MBLG-A_VERB/(A_LUO+(A_LUO=0)*$B9)))/A_MPG_E,0))/(A_IST+(A_IST=0))-1)))/MAX(0.1,N(Parameter!$M$21)))) -> 34.833367 | P9: =SUMPRODUCT((A_LIFT="Aussen")*((A_FACH>0)*A_FACH*(1+(A_KAPR>0)*((A_FINF*A_FINV+(1-A_FINF)*ROUNDUP((A_VERB/(A_LUO+(A_LUO=0)*$B9)+(A_MBLG>A_VERB/(A_LUO+(A_LUO=0)*$B9))*(A_MBLG-A_VERB/(A_LUO+(A_LUO=0)*$B9)))/A_MPG_E,0)*A_MPG_E)>A_KAPR)*((A_FINF*A_FINV+(1-A_FINF)*ROUNDUP((A_VERB/(A_LUO+(A_LUO=0)*$B9)+(A_MBLG>A_VERB/(A_LUO+(A_LUO=0)*$B9))*(A_MBLG-A_VERB/(A_LUO+(A_LUO=0)*$B9)))/A_MPG_E,0)*A_MPG_E)/(A_KAPR+(A_KAPR=0))-1))+(A_FACH=0)*((1-A_LOSE)*(A_GPT>0)*(A_FINF*A_FINN+(1-A_FINF)*ROUNDUP((A_VERB/(A_LUO+(A_LUO=0)*$B9)+(A_MBLG>A_VERB/(A_LUO+(A_LUO=0)*$B9))*(A_MBLG-A_VERB/(A_LUO+(A_LUO=0)*$B9)))/A_MPG_E,0))/(A_GPT+(A_GPT=0))+A_LOSE*((A_FINF*A_FINN+(1-A_FINF)*ROUNDUP((A_VERB/(A_LUO+(A_LUO=0)*$B9)+(A_MBLG>A_VERB/(A_LUO+(A_LUO=0)*$B9))*(A_MBLG-A_VERB/(A_LUO+(A_LUO=0)*$B9)))/A_MPG_E,0))>0)*A_LA*(1+(A_IST>0)*((A_FINF*A_FINN+(1-A_FINF)*ROUNDUP((A_VERB/(A_LUO+(A_LUO=0)*$B9)+(A_MBLG>A_VERB/(A_LUO+(A_LUO=0)*$B9))*(A_MBLG-A_VERB/(A_LUO+(A_LUO=0)*$B9)))/A_MPG_E,0))>A_IST)*((A_FINF*A_FINN+(1-A_FINF)*ROUNDUP((A_VERB/(A_LUO+(A_LUO=0)*$B9)+(A_MBLG>A_VERB/(A_LUO+(A_LUO=0)*$B9))*(A_MBLG-A_VERB/(A_LUO+(A_LUO=0)*$B9)))/A_MPG_E,0))/(A_IST+(A_IST=0))-1)))/MAX(0.1,N(Parameter!$M$21)))) -> 0
A10: B – Ziel-LU | B10: =Parameter!$A$27 -> 3 | C10: =M10/Parameter!$E$5 -> 1.2831972 | D10: =N10/Parameter!$E$6 -> 1.6318182 | E10: =O10/Parameter!$E$7 -> 0.68928972 | F10: =(N10+O10)/(Parameter!$E$6+Parameter!$E$7) -> 1.160554 | G10: =(M10+N10+O10)/Parameter!$E$8 -> 1.201435 | H10: =IF(AND(M10<=Parameter!$E$5,N10+O10<=Parameter!$E$6+Parameter!$E$7),"JA","NEIN") -> NEIN | I10: =MAX(0,M10-Parameter!$E$5)+MAX(0,N10+O10-Parameter!$E$6-Parameter!$E$7)+P10 -> 30.215256 | J10: =SUMPRODUCT((A_FINF*A_FINV+(1-A_FINF)*ROUNDUP((A_VERB/(A_LUO+(A_LUO=0)*$B10)+(A_MBLG>A_VERB/(A_LUO+(A_LUO=0)*$B10))*(A_MBLG-A_VERB/(A_LUO+(A_LUO=0)*$B10)))/A_MPG_E,0)*A_MPG_E)*A_PREIS) -> 6597211.3 | K10: =J10-$J$5 -> 3146165.1 | L10: =(M10+N10+O10+P10)-($M$5+$N$5+$O$5+$P$5) -> 29.300667 | M10: =SUMPRODUCT((A_LIFT=1)*((A_FACH>0)*A_FACH*(1+(A_KAPR>0)*((A_FINF*A_FINV+(1-A_FINF)*ROUNDUP((A_VERB/(A_LUO+(A_LUO=0)*$B10)+(A_MBLG>A_VERB/(A_LUO+(A_LUO=0)*$B10))*(A_MBLG-A_VERB/(A_LUO+(A_LUO=0)*$B10)))/A_MPG_E,0)*A_MPG_E)>A_KAPR)*((A_FINF*A_FINV+(1-A_FINF)*ROUNDUP((A_VERB/(A_LUO+(A_LUO=0)*$B10)+(A_MBLG>A_VERB/(A_LUO+(A_LUO=0)*$B10))*(A_MBLG-A_VERB/(A_LUO+(A_LUO=0)*$B10)))/A_MPG_E,0)*A_MPG_E)/(A_KAPR+(A_KAPR=0))-1))+(A_FACH=0)*((1-A_LOSE)*(A_GPT>0)*(A_FINF*A_FINN+(1-A_FINF)*ROUNDUP((A_VERB/(A_LUO+(A_LUO=0)*$B10)+(A_MBLG>A_VERB/(A_LUO+(A_LUO=0)*$B10))*(A_MBLG-A_VERB/(A_LUO+(A_LUO=0)*$B10)))/A_MPG_E,0))/(A_GPT+(A_GPT=0))+A_LOSE*((A_FINF*A_FINN+(1-A_FINF)*ROUNDUP((A_VERB/(A_LUO+(A_LUO=0)*$B10)+(A_MBLG>A_VERB/(A_LUO+(A_LUO=0)*$B10))*(A_MBLG-A_VERB/(A_LUO+(A_LUO=0)*$B10)))/A_MPG_E,0))>0)*A_LA*(1+(A_IST>0)*((A_FINF*A_FINN+(1-A_FINF)*ROUNDUP((A_VERB/(A_LUO+(A_LUO=0)*$B10)+(A_MBLG>A_VERB/(A_LUO+(A_LUO=0)*$B10))*(A_MBLG-A_VERB/(A_LUO+(A_LUO=0)*$B10)))/A_MPG_E,0))>A_IST)*((A_FINF*A_FINN+(1-A_FINF)*ROUNDUP((A_VERB/(A_LUO+(A_LUO=0)*$B10)+(A_MBLG>A_VERB/(A_LUO+(A_LUO=0)*$B10))*(A_MBLG-A_VERB/(A_LUO+(A_LUO=0)*$B10)))/A_MPG_E,0))/(A_IST+(A_IST=0))-1)))/MAX(0.1,N(Parameter!$M$21)))) -> 64.159861 | N10: =SUMPRODUCT((A_LIFT=2)*((A_FACH>0)*A_FACH*(1+(A_KAPR>0)*((A_FINF*A_FINV+(1-A_FINF)*ROUNDUP((A_VERB/(A_LUO+(A_LUO=0)*$B10)+(A_MBLG>A_VERB/(A_LUO+(A_LUO=0)*$B10))*(A_MBLG-A_VERB/(A_LUO+(A_LUO=0)*$B10)))/A_MPG_E,0)*A_MPG_E)>A_KAPR)*((A_FINF*A_FINV+(1-A_FINF)*ROUNDUP((A_VERB/(A_LUO+(A_LUO=0)*$B10)+(A_MBLG>A_VERB/(A_LUO+(A_LUO=0)*$B10))*(A_MBLG-A_VERB/(A_LUO+(A_LUO=0)*$B10)))/A_MPG_E,0)*A_MPG_E)/(A_KAPR+(A_KAPR=0))-1))+(A_FACH=0)*((1-A_LOSE)*(A_GPT>0)*(A_FINF*A_FINN+(1-A_FINF)*ROUNDUP((A_VERB/(A_LUO+(A_LUO=0)*$B10)+(A_MBLG>A_VERB/(A_LUO+(A_LUO=0)*$B10))*(A_MBLG-A_VERB/(A_LUO+(A_LUO=0)*$B10)))/A_MPG_E,0))/(A_GPT+(A_GPT=0))+A_LOSE*((A_FINF*A_FINN+(1-A_FINF)*ROUNDUP((A_VERB/(A_LUO+(A_LUO=0)*$B10)+(A_MBLG>A_VERB/(A_LUO+(A_LUO=0)*$B10))*(A_MBLG-A_VERB/(A_LUO+(A_LUO=0)*$B10)))/A_MPG_E,0))>0)*A_LA*(1+(A_IST>0)*((A_FINF*A_FINN+(1-A_FINF)*ROUNDUP((A_VERB/(A_LUO+(A_LUO=0)*$B10)+(A_MBLG>A_VERB/(A_LUO+(A_LUO=0)*$B10))*(A_MBLG-A_VERB/(A_LUO+(A_LUO=0)*$B10)))/A_MPG_E,0))>A_IST)*((A_FINF*A_FINN+(1-A_FINF)*ROUNDUP((A_VERB/(A_LUO+(A_LUO=0)*$B10)+(A_MBLG>A_VERB/(A_LUO+(A_LUO=0)*$B10))*(A_MBLG-A_VERB/(A_LUO+(A_LUO=0)*$B10)))/A_MPG_E,0))/(A_IST+(A_IST=0))-1)))/MAX(0.1,N(Parameter!$M$21)))) -> 81.590909 | O10: =SUMPRODUCT((A_LIFT=3)*((A_FACH>0)*A_FACH*(1+(A_KAPR>0)*((A_FINF*A_FINV+(1-A_FINF)*ROUNDUP((A_VERB/(A_LUO+(A_LUO=0)*$B10)+(A_MBLG>A_VERB/(A_LUO+(A_LUO=0)*$B10))*(A_MBLG-A_VERB/(A_LUO+(A_LUO=0)*$B10)))/A_MPG_E,0)*A_MPG_E)>A_KAPR)*((A_FINF*A_FINV+(1-A_FINF)*ROUNDUP((A_VERB/(A_LUO+(A_LUO=0)*$B10)+(A_MBLG>A_VERB/(A_LUO+(A_LUO=0)*$B10))*(A_MBLG-A_VERB/(A_LUO+(A_LUO=0)*$B10)))/A_MPG_E,0)*A_MPG_E)/(A_KAPR+(A_KAPR=0))-1))+(A_FACH=0)*((1-A_LOSE)*(A_GPT>0)*(A_FINF*A_FINN+(1-A_FINF)*ROUNDUP((A_VERB/(A_LUO+(A_LUO=0)*$B10)+(A_MBLG>A_VERB/(A_LUO+(A_LUO=0)*$B10))*(A_MBLG-A_VERB/(A_LUO+(A_LUO=0)*$B10)))/A_MPG_E,0))/(A_GPT+(A_GPT=0))+A_LOSE*((A_FINF*A_FINN+(1-A_FINF)*ROUNDUP((A_VERB/(A_LUO+(A_LUO=0)*$B10)+(A_MBLG>A_VERB/(A_LUO+(A_LUO=0)*$B10))*(A_MBLG-A_VERB/(A_LUO+(A_LUO=0)*$B10)))/A_MPG_E,0))>0)*A_LA*(1+(A_IST>0)*((A_FINF*A_FINN+(1-A_FINF)*ROUNDUP((A_VERB/(A_LUO+(A_LUO=0)*$B10)+(A_MBLG>A_VERB/(A_LUO+(A_LUO=0)*$B10))*(A_MBLG-A_VERB/(A_LUO+(A_LUO=0)*$B10)))/A_MPG_E,0))>A_IST)*((A_FINF*A_FINN+(1-A_FINF)*ROUNDUP((A_VERB/(A_LUO+(A_LUO=0)*$B10)+(A_MBLG>A_VERB/(A_LUO+(A_LUO=0)*$B10))*(A_MBLG-A_VERB/(A_LUO+(A_LUO=0)*$B10)))/A_MPG_E,0))/(A_IST+(A_IST=0))-1)))/MAX(0.1,N(Parameter!$M$21)))) -> 34.464486 | P10: =SUMPRODUCT((A_LIFT="Aussen")*((A_FACH>0)*A_FACH*(1+(A_KAPR>0)*((A_FINF*A_FINV+(1-A_FINF)*ROUNDUP((A_VERB/(A_LUO+(A_LUO=0)*$B10)+(A_MBLG>A_VERB/(A_LUO+(A_LUO=0)*$B10))*(A_MBLG-A_VERB/(A_LUO+(A_LUO=0)*$B10)))/A_MPG_E,0)*A_MPG_E)>A_KAPR)*((A_FINF*A_FINV+(1-A_FINF)*ROUNDUP((A_VERB/(A_LUO+(A_LUO=0)*$B10)+(A_MBLG>A_VERB/(A_LUO+(A_LUO=0)*$B10))*(A_MBLG-A_VERB/(A_LUO+(A_LUO=0)*$B10)))/A_MPG_E,0)*A_MPG_E)/(A_KAPR+(A_KAPR=0))-1))+(A_FACH=0)*((1-A_LOSE)*(A_GPT>0)*(A_FINF*A_FINN+(1-A_FINF)*ROUNDUP((A_VERB/(A_LUO+(A_LUO=0)*$B10)+(A_MBLG>A_VERB/(A_LUO+(A_LUO=0)*$B10))*(A_MBLG-A_VERB/(A_LUO+(A_LUO=0)*$B10)))/A_MPG_E,0))/(A_GPT+(A_GPT=0))+A_LOSE*((A_FINF*A_FINN+(1-A_FINF)*ROUNDUP((A_VERB/(A_LUO+(A_LUO=0)*$B10)+(A_MBLG>A_VERB/(A_LUO+(A_LUO=0)*$B10))*(A_MBLG-A_VERB/(A_LUO+(A_LUO=0)*$B10)))/A_MPG_E,0))>0)*A_LA*(1+(A_IST>0)*((A_FINF*A_FINN+(1-A_FINF)*ROUNDUP((A_VERB/(A_LUO+(A_LUO=0)*$B10)+(A_MBLG>A_VERB/(A_LUO+(A_LUO=0)*$B10))*(A_MBLG-A_VERB/(A_LUO+(A_LUO=0)*$B10)))/A_MPG_E,0))>A_IST)*((A_FINF*A_FINN+(1-A_FINF)*ROUNDUP((A_VERB/(A_LUO+(A_LUO=0)*$B10)+(A_MBLG>A_VERB/(A_LUO+(A_LUO=0)*$B10))*(A_MBLG-A_VERB/(A_LUO+(A_LUO=0)*$B10)))/A_MPG_E,0))/(A_IST+(A_IST=0))-1)))/MAX(0.1,N(Parameter!$M$21)))) -> 0
A11: B – Ziel-LU | B11: =Parameter!$A$28 -> 4 | C11: =M11/Parameter!$E$5 -> 1.2439223 | D11: =N11/Parameter!$E$6 -> 1.5534848 | E11: =O11/Parameter!$E$7 -> 0.67821746 | F11: =(N11+O11)/(Parameter!$E$6+Parameter!$E$7) -> 1.1158512 | G11: =(M11+N11+O11)/Parameter!$E$8 -> 1.1585415 | H11: =IF(AND(M11<=Parameter!$E$5,N11+O11<=Parameter!$E$6+Parameter!$E$7),"JA","NEIN") -> NEIN | I11: =MAX(0,M11-Parameter!$E$5)+MAX(0,N11+O11-Parameter!$E$6-Parameter!$E$7)+P11 -> 23.781229 | J11: =SUMPRODUCT((A_FINF*A_FINV+(1-A_FINF)*ROUNDUP((A_VERB/(A_LUO+(A_LUO=0)*$B11)+(A_MBLG>A_VERB/(A_LUO+(A_LUO=0)*$B11))*(A_MBLG-A_VERB/(A_LUO+(A_LUO=0)*$B11)))/A_MPG_E,0)*A_MPG_E)*A_PREIS) -> 6188765.1 | K11: =J11-$J$5 -> 2737718.9 | L11: =(M11+N11+O11+P11)-($M$5+$N$5+$O$5+$P$5) -> 22.86664 | M11: =SUMPRODUCT((A_LIFT=1)*((A_FACH>0)*A_FACH*(1+(A_KAPR>0)*((A_FINF*A_FINV+(1-A_FINF)*ROUNDUP((A_VERB/(A_LUO+(A_LUO=0)*$B11)+(A_MBLG>A_VERB/(A_LUO+(A_LUO=0)*$B11))*(A_MBLG-A_VERB/(A_LUO+(A_LUO=0)*$B11)))/A_MPG_E,0)*A_MPG_E)>A_KAPR)*((A_FINF*A_FINV+(1-A_FINF)*ROUNDUP((A_VERB/(A_LUO+(A_LUO=0)*$B11)+(A_MBLG>A_VERB/(A_LUO+(A_LUO=0)*$B11))*(A_MBLG-A_VERB/(A_LUO+(A_LUO=0)*$B11)))/A_MPG_E,0)*A_MPG_E)/(A_KAPR+(A_KAPR=0))-1))+(A_FACH=0)*((1-A_LOSE)*(A_GPT>0)*(A_FINF*A_FINN+(1-A_FINF)*ROUNDUP((A_VERB/(A_LUO+(A_LUO=0)*$B11)+(A_MBLG>A_VERB/(A_LUO+(A_LUO=0)*$B11))*(A_MBLG-A_VERB/(A_LUO+(A_LUO=0)*$B11)))/A_MPG_E,0))/(A_GPT+(A_GPT=0))+A_LOSE*((A_FINF*A_FINN+(1-A_FINF)*ROUNDUP((A_VERB/(A_LUO+(A_LUO=0)*$B11)+(A_MBLG>A_VERB/(A_LUO+(A_LUO=0)*$B11))*(A_MBLG-A_VERB/(A_LUO+(A_LUO=0)*$B11)))/A_MPG_E,0))>0)*A_LA*(1+(A_IST>0)*((A_FINF*A_FINN+(1-A_FINF)*ROUNDUP((A_VERB/(A_LUO+(A_LUO=0)*$B11)+(A_MBLG>A_VERB/(A_LUO+(A_LUO=0)*$B11))*(A_MBLG-A_VERB/(A_LUO+(A_LUO=0)*$B11)))/A_MPG_E,0))>A_IST)*((A_FINF*A_FINN+(1-A_FINF)*ROUNDUP((A_VERB/(A_LUO+(A_LUO=0)*$B11)+(A_MBLG>A_VERB/(A_LUO+(A_LUO=0)*$B11))*(A_MBLG-A_VERB/(A_LUO+(A_LUO=0)*$B11)))/A_MPG_E,0))/(A_IST+(A_IST=0))-1)))/MAX(0.1,N(Parameter!$M$21)))) -> 62.196114 | N11: =SUMPRODUCT((A_LIFT=2)*((A_FACH>0)*A_FACH*(1+(A_KAPR>0)*((A_FINF*A_FINV+(1-A_FINF)*ROUNDUP((A_VERB/(A_LUO+(A_LUO=0)*$B11)+(A_MBLG>A_VERB/(A_LUO+(A_LUO=0)*$B11))*(A_MBLG-A_VERB/(A_LUO+(A_LUO=0)*$B11)))/A_MPG_E,0)*A_MPG_E)>A_KAPR)*((A_FINF*A_FINV+(1-A_FINF)*ROUNDUP((A_VERB/(A_LUO+(A_LUO=0)*$B11)+(A_MBLG>A_VERB/(A_LUO+(A_LUO=0)*$B11))*(A_MBLG-A_VERB/(A_LUO+(A_LUO=0)*$B11)))/A_MPG_E,0)*A_MPG_E)/(A_KAPR+(A_KAPR=0))-1))+(A_FACH=0)*((1-A_LOSE)*(A_GPT>0)*(A_FINF*A_FINN+(1-A_FINF)*ROUNDUP((A_VERB/(A_LUO+(A_LUO=0)*$B11)+(A_MBLG>A_VERB/(A_LUO+(A_LUO=0)*$B11))*(A_MBLG-A_VERB/(A_LUO+(A_LUO=0)*$B11)))/A_MPG_E,0))/(A_GPT+(A_GPT=0))+A_LOSE*((A_FINF*A_FINN+(1-A_FINF)*ROUNDUP((A_VERB/(A_LUO+(A_LUO=0)*$B11)+(A_MBLG>A_VERB/(A_LUO+(A_LUO=0)*$B11))*(A_MBLG-A_VERB/(A_LUO+(A_LUO=0)*$B11)))/A_MPG_E,0))>0)*A_LA*(1+(A_IST>0)*((A_FINF*A_FINN+(1-A_FINF)*ROUNDUP((A_VERB/(A_LUO+(A_LUO=0)*$B11)+(A_MBLG>A_VERB/(A_LUO+(A_LUO=0)*$B11))*(A_MBLG-A_VERB/(A_LUO+(A_LUO=0)*$B11)))/A_MPG_E,0))>A_IST)*((A_FINF*A_FINN+(1-A_FINF)*ROUNDUP((A_VERB/(A_LUO+(A_LUO=0)*$B11)+(A_MBLG>A_VERB/(A_LUO+(A_LUO=0)*$B11))*(A_MBLG-A_VERB/(A_LUO+(A_LUO=0)*$B11)))/A_MPG_E,0))/(A_IST+(A_IST=0))-1)))/MAX(0.1,N(Parameter!$M$21)))) -> 77.674242 | O11: =SUMPRODUCT((A_LIFT=3)*((A_FACH>0)*A_FACH*(1+(A_KAPR>0)*((A_FINF*A_FINV+(1-A_FINF)*ROUNDUP((A_VERB/(A_LUO+(A_LUO=0)*$B11)+(A_MBLG>A_VERB/(A_LUO+(A_LUO=0)*$B11))*(A_MBLG-A_VERB/(A_LUO+(A_LUO=0)*$B11)))/A_MPG_E,0)*A_MPG_E)>A_KAPR)*((A_FINF*A_FINV+(1-A_FINF)*ROUNDUP((A_VERB/(A_LUO+(A_LUO=0)*$B11)+(A_MBLG>A_VERB/(A_LUO+(A_LUO=0)*$B11))*(A_MBLG-A_VERB/(A_LUO+(A_LUO=0)*$B11)))/A_MPG_E,0)*A_MPG_E)/(A_KAPR+(A_KAPR=0))-1))+(A_FACH=0)*((1-A_LOSE)*(A_GPT>0)*(A_FINF*A_FINN+(1-A_FINF)*ROUNDUP((A_VERB/(A_LUO+(A_LUO=0)*$B11)+(A_MBLG>A_VERB/(A_LUO+(A_LUO=0)*$B11))*(A_MBLG-A_VERB/(A_LUO+(A_LUO=0)*$B11)))/A_MPG_E,0))/(A_GPT+(A_GPT=0))+A_LOSE*((A_FINF*A_FINN+(1-A_FINF)*ROUNDUP((A_VERB/(A_LUO+(A_LUO=0)*$B11)+(A_MBLG>A_VERB/(A_LUO+(A_LUO=0)*$B11))*(A_MBLG-A_VERB/(A_LUO+(A_LUO=0)*$B11)))/A_MPG_E,0))>0)*A_LA*(1+(A_IST>0)*((A_FINF*A_FINN+(1-A_FINF)*ROUNDUP((A_VERB/(A_LUO+(A_LUO=0)*$B11)+(A_MBLG>A_VERB/(A_LUO+(A_LUO=0)*$B11))*(A_MBLG-A_VERB/(A_LUO+(A_LUO=0)*$B11)))/A_MPG_E,0))>A_IST)*((A_FINF*A_FINN+(1-A_FINF)*ROUNDUP((A_VERB/(A_LUO+(A_LUO=0)*$B11)+(A_MBLG>A_VERB/(A_LUO+(A_LUO=0)*$B11))*(A_MBLG-A_VERB/(A_LUO+(A_LUO=0)*$B11)))/A_MPG_E,0))/(A_IST+(A_IST=0))-1)))/MAX(0.1,N(Parameter!$M$21)))) -> 33.910873 | P11: =SUMPRODUCT((A_LIFT="Aussen")*((A_FACH>0)*A_FACH*(1+(A_KAPR>0)*((A_FINF*A_FINV+(1-A_FINF)*ROUNDUP((A_VERB/(A_LUO+(A_LUO=0)*$B11)+(A_MBLG>A_VERB/(A_LUO+(A_LUO=0)*$B11))*(A_MBLG-A_VERB/(A_LUO+(A_LUO=0)*$B11)))/A_MPG_E,0)*A_MPG_E)>A_KAPR)*((A_FINF*A_FINV+(1-A_FINF)*ROUNDUP((A_VERB/(A_LUO+(A_LUO=0)*$B11)+(A_MBLG>A_VERB/(A_LUO+(A_LUO=0)*$B11))*(A_MBLG-A_VERB/(A_LUO+(A_LUO=0)*$B11)))/A_MPG_E,0)*A_MPG_E)/(A_KAPR+(A_KAPR=0))-1))+(A_FACH=0)*((1-A_LOSE)*(A_GPT>0)*(A_FINF*A_FINN+(1-A_FINF)*ROUNDUP((A_VERB/(A_LUO+(A_LUO=0)*$B11)+(A_MBLG>A_VERB/(A_LUO+(A_LUO=0)*$B11))*(A_MBLG-A_VERB/(A_LUO+(A_LUO=0)*$B11)))/A_MPG_E,0))/(A_GPT+(A_GPT=0))+A_LOSE*((A_FINF*A_FINN+(1-A_FINF)*ROUNDUP((A_VERB/(A_LUO+(A_LUO=0)*$B11)+(A_MBLG>A_VERB/(A_LUO+(A_LUO=0)*$B11))*(A_MBLG-A_VERB/(A_LUO+(A_LUO=0)*$B11)))/A_MPG_E,0))>0)*A_LA*(1+(A_IST>0)*((A_FINF*A_FINN+(1-A_FINF)*ROUNDUP((A_VERB/(A_LUO+(A_LUO=0)*$B11)+(A_MBLG>A_VERB/(A_LUO+(A_LUO=0)*$B11))*(A_MBLG-A_VERB/(A_LUO+(A_LUO=0)*$B11)))/A_MPG_E,0))>A_IST)*((A_FINF*A_FINN+(1-A_FINF)*ROUNDUP((A_VERB/(A_LUO+(A_LUO=0)*$B11)+(A_MBLG>A_VERB/(A_LUO+(A_LUO=0)*$B11))*(A_MBLG-A_VERB/(A_LUO+(A_LUO=0)*$B11)))/A_MPG_E,0))/(A_IST+(A_IST=0))-1)))/MAX(0.1,N(Parameter!$M$21)))) -> 0
A12: B – Ziel-LU | B12: =Parameter!$A$29 -> 5 | C12: =M12/Parameter!$E$5 -> 1.2284167 | D12: =N12/Parameter!$E$6 -> 1.5118182 | E12: =O12/Parameter!$E$7 -> 0.67437131 | F12: =(N12+O12)/(Parameter!$E$6+Parameter!$E$7) -> 1.0930947 | G12: =(M12+N12+O12)/Parameter!$E$8 -> 1.1382021 | H12: =IF(AND(M12<=Parameter!$E$5,N12+O12<=Parameter!$E$6+Parameter!$E$7),"JA","NEIN") -> NEIN | I12: =MAX(0,M12-Parameter!$E$5)+MAX(0,N12+O12-Parameter!$E$6-Parameter!$E$7)+P12 -> 20.730309 | J12: =SUMPRODUCT((A_FINF*A_FINV+(1-A_FINF)*ROUNDUP((A_VERB/(A_LUO+(A_LUO=0)*$B12)+(A_MBLG>A_VERB/(A_LUO+(A_LUO=0)*$B12))*(A_MBLG-A_VERB/(A_LUO+(A_LUO=0)*$B12)))/A_MPG_E,0)*A_MPG_E)*A_PREIS) -> 5942935.1 | K12: =J12-$J$5 -> 2491888.8 | L12: =(M12+N12+O12+P12)-($M$5+$N$5+$O$5+$P$5) -> 19.81572 | M12: =SUMPRODUCT((A_LIFT=1)*((A_FACH>0)*A_FACH*(1+(A_KAPR>0)*((A_FINF*A_FINV+(1-A_FINF)*ROUNDUP((A_VERB/(A_LUO+(A_LUO=0)*$B12)+(A_MBLG>A_VERB/(A_LUO+(A_LUO=0)*$B12))*(A_MBLG-A_VERB/(A_LUO+(A_LUO=0)*$B12)))/A_MPG_E,0)*A_MPG_E)>A_KAPR)*((A_FINF*A_FINV+(1-A_FINF)*ROUNDUP((A_VERB/(A_LUO+(A_LUO=0)*$B12)+(A_MBLG>A_VERB/(A_LUO+(A_LUO=0)*$B12))*(A_MBLG-A_VERB/(A_LUO+(A_LUO=0)*$B12)))/A_MPG_E,0)*A_MPG_E)/(A_KAPR+(A_KAPR=0))-1))+(A_FACH=0)*((1-A_LOSE)*(A_GPT>0)*(A_FINF*A_FINN+(1-A_FINF)*ROUNDUP((A_VERB/(A_LUO+(A_LUO=0)*$B12)+(A_MBLG>A_VERB/(A_LUO+(A_LUO=0)*$B12))*(A_MBLG-A_VERB/(A_LUO+(A_LUO=0)*$B12)))/A_MPG_E,0))/(A_GPT+(A_GPT=0))+A_LOSE*((A_FINF*A_FINN+(1-A_FINF)*ROUNDUP((A_VERB/(A_LUO+(A_LUO=0)*$B12)+(A_MBLG>A_VERB/(A_LUO+(A_LUO=0)*$B12))*(A_MBLG-A_VERB/(A_LUO+(A_LUO=0)*$B12)))/A_MPG_E,0))>0)*A_LA*(1+(A_IST>0)*((A_FINF*A_FINN+(1-A_FINF)*ROUNDUP((A_VERB/(A_LUO+(A_LUO=0)*$B12)+(A_MBLG>A_VERB/(A_LUO+(A_LUO=0)*$B12))*(A_MBLG-A_VERB/(A_LUO+(A_LUO=0)*$B12)))/A_MPG_E,0))>A_IST)*((A_FINF*A_FINN+(1-A_FINF)*ROUNDUP((A_VERB/(A_LUO+(A_LUO=0)*$B12)+(A_MBLG>A_VERB/(A_LUO+(A_LUO=0)*$B12))*(A_MBLG-A_VERB/(A_LUO+(A_LUO=0)*$B12)))/A_MPG_E,0))/(A_IST+(A_IST=0))-1)))/MAX(0.1,N(Parameter!$M$21)))) -> 61.420835 | N12: =SUMPRODUCT((A_LIFT=2)*((A_FACH>0)*A_FACH*(1+(A_KAPR>0)*((A_FINF*A_FINV+(1-A_FINF)*ROUNDUP((A_VERB/(A_LUO+(A_LUO=0)*$B12)+(A_MBLG>A_VERB/(A_LUO+(A_LUO=0)*$B12))*(A_MBLG-A_VERB/(A_LUO+(A_LUO=0)*$B12)))/A_MPG_E,0)*A_MPG_E)>A_KAPR)*((A_FINF*A_FINV+(1-A_FINF)*ROUNDUP((A_VERB/(A_LUO+(A_LUO=0)*$B12)+(A_MBLG>A_VERB/(A_LUO+(A_LUO=0)*$B12))*(A_MBLG-A_VERB/(A_LUO+(A_LUO=0)*$B12)))/A_MPG_E,0)*A_MPG_E)/(A_KAPR+(A_KAPR=0))-1))+(A_FACH=0)*((1-A_LOSE)*(A_GPT>0)*(A_FINF*A_FINN+(1-A_FINF)*ROUNDUP((A_VERB/(A_LUO+(A_LUO=0)*$B12)+(A_MBLG>A_VERB/(A_LUO+(A_LUO=0)*$B12))*(A_MBLG-A_VERB/(A_LUO+(A_LUO=0)*$B12)))/A_MPG_E,0))/(A_GPT+(A_GPT=0))+A_LOSE*((A_FINF*A_FINN+(1-A_FINF)*ROUNDUP((A_VERB/(A_LUO+(A_LUO=0)*$B12)+(A_MBLG>A_VERB/(A_LUO+(A_LUO=0)*$B12))*(A_MBLG-A_VERB/(A_LUO+(A_LUO=0)*$B12)))/A_MPG_E,0))>0)*A_LA*(1+(A_IST>0)*((A_FINF*A_FINN+(1-A_FINF)*ROUNDUP((A_VERB/(A_LUO+(A_LUO=0)*$B12)+(A_MBLG>A_VERB/(A_LUO+(A_LUO=0)*$B12))*(A_MBLG-A_VERB/(A_LUO+(A_LUO=0)*$B12)))/A_MPG_E,0))>A_IST)*((A_FINF*A_FINN+(1-A_FINF)*ROUNDUP((A_VERB/(A_LUO+(A_LUO=0)*$B12)+(A_MBLG>A_VERB/(A_LUO+(A_LUO=0)*$B12))*(A_MBLG-A_VERB/(A_LUO+(A_LUO=0)*$B12)))/A_MPG_E,0))/(A_IST+(A_IST=0))-1)))/MAX(0.1,N(Parameter!$M$21)))) -> 75.590909 | O12: =SUMPRODUCT((A_LIFT=3)*((A_FACH>0)*A_FACH*(1+(A_KAPR>0)*((A_FINF*A_FINV+(1-A_FINF)*ROUNDUP((A_VERB/(A_LUO+(A_LUO=0)*$B12)+(A_MBLG>A_VERB/(A_LUO+(A_LUO=0)*$B12))*(A_MBLG-A_VERB/(A_LUO+(A_LUO=0)*$B12)))/A_MPG_E,0)*A_MPG_E)>A_KAPR)*((A_FINF*A_FINV+(1-A_FINF)*ROUNDUP((A_VERB/(A_LUO+(A_LUO=0)*$B12)+(A_MBLG>A_VERB/(A_LUO+(A_LUO=0)*$B12))*(A_MBLG-A_VERB/(A_LUO+(A_LUO=0)*$B12)))/A_MPG_E,0)*A_MPG_E)/(A_KAPR+(A_KAPR=0))-1))+(A_FACH=0)*((1-A_LOSE)*(A_GPT>0)*(A_FINF*A_FINN+(1-A_FINF)*ROUNDUP((A_VERB/(A_LUO+(A_LUO=0)*$B12)+(A_MBLG>A_VERB/(A_LUO+(A_LUO=0)*$B12))*(A_MBLG-A_VERB/(A_LUO+(A_LUO=0)*$B12)))/A_MPG_E,0))/(A_GPT+(A_GPT=0))+A_LOSE*((A_FINF*A_FINN+(1-A_FINF)*ROUNDUP((A_VERB/(A_LUO+(A_LUO=0)*$B12)+(A_MBLG>A_VERB/(A_LUO+(A_LUO=0)*$B12))*(A_MBLG-A_VERB/(A_LUO+(A_LUO=0)*$B12)))/A_MPG_E,0))>0)*A_LA*(1+(A_IST>0)*((A_FINF*A_FINN+(1-A_FINF)*ROUNDUP((A_VERB/(A_LUO+(A_LUO=0)*$B12)+(A_MBLG>A_VERB/(A_LUO+(A_LUO=0)*$B12))*(A_MBLG-A_VERB/(A_LUO+(A_LUO=0)*$B12)))/A_MPG_E,0))>A_IST)*((A_FINF*A_FINN+(1-A_FINF)*ROUNDUP((A_VERB/(A_LUO+(A_LUO=0)*$B12)+(A_MBLG>A_VERB/(A_LUO+(A_LUO=0)*$B12))*(A_MBLG-A_VERB/(A_LUO+(A_LUO=0)*$B12)))/A_MPG_E,0))/(A_IST+(A_IST=0))-1)))/MAX(0.1,N(Parameter!$M$21)))) -> 33.718565 | P12: =SUMPRODUCT((A_LIFT="Aussen")*((A_FACH>0)*A_FACH*(1+(A_KAPR>0)*((A_FINF*A_FINV+(1-A_FINF)*ROUNDUP((A_VERB/(A_LUO+(A_LUO=0)*$B12)+(A_MBLG>A_VERB/(A_LUO+(A_LUO=0)*$B12))*(A_MBLG-A_VERB/(A_LUO+(A_LUO=0)*$B12)))/A_MPG_E,0)*A_MPG_E)>A_KAPR)*((A_FINF*A_FINV+(1-A_FINF)*ROUNDUP((A_VERB/(A_LUO+(A_LUO=0)*$B12)+(A_MBLG>A_VERB/(A_LUO+(A_LUO=0)*$B12))*(A_MBLG-A_VERB/(A_LUO+(A_LUO=0)*$B12)))/A_MPG_E,0)*A_MPG_E)/(A_KAPR+(A_KAPR=0))-1))+(A_FACH=0)*((1-A_LOSE)*(A_GPT>0)*(A_FINF*A_FINN+(1-A_FINF)*ROUNDUP((A_VERB/(A_LUO+(A_LUO=0)*$B12)+(A_MBLG>A_VERB/(A_LUO+(A_LUO=0)*$B12))*(A_MBLG-A_VERB/(A_LUO+(A_LUO=0)*$B12)))/A_MPG_E,0))/(A_GPT+(A_GPT=0))+A_LOSE*((A_FINF*A_FINN+(1-A_FINF)*ROUNDUP((A_VERB/(A_LUO+(A_LUO=0)*$B12)+(A_MBLG>A_VERB/(A_LUO+(A_LUO=0)*$B12))*(A_MBLG-A_VERB/(A_LUO+(A_LUO=0)*$B12)))/A_MPG_E,0))>0)*A_LA*(1+(A_IST>0)*((A_FINF*A_FINN+(1-A_FINF)*ROUNDUP((A_VERB/(A_LUO+(A_LUO=0)*$B12)+(A_MBLG>A_VERB/(A_LUO+(A_LUO=0)*$B12))*(A_MBLG-A_VERB/(A_LUO+(A_LUO=0)*$B12)))/A_MPG_E,0))>A_IST)*((A_FINF*A_FINN+(1-A_FINF)*ROUNDUP((A_VERB/(A_LUO+(A_LUO=0)*$B12)+(A_MBLG>A_VERB/(A_LUO+(A_LUO=0)*$B12))*(A_MBLG-A_VERB/(A_LUO+(A_LUO=0)*$B12)))/A_MPG_E,0))/(A_IST+(A_IST=0))-1)))/MAX(0.1,N(Parameter!$M$21)))) -> 0
